Workbook

Sheet รวมรายได้
A1: รายรับเดือนเมษายน2565
A2: DATE | B2: Cash | C2: Credit Card | E2: Tranfer Money | G2: E-WALLET | H2: Paypal | I2: qr paymet | J2: หักคอม | K2: ARP | L2: TOTAL
C3: Front Office | D3: Online | E3: KBANK | F3: KTB
A5: 1 | L5: =B5+C5+D5+E5+F5+G5+H5+I5+J5+K5 -> 0
A6: 2 | C6: 45800 | D6: 319140 | E6: 913406 | F6: 343180 | G6: 38940 | J6: 23739 | K6: 8000 | L6: =B6+C6+D6+E6+F6+G6+H6+I6+J6+K6 -> 1692205
A7: 3 | B7: ='03.04.65'!F110 -> 600 | C7: ='03.04.65'!G110 -> 23000 | D7: ='03.04.65'!H110 -> 200450 | E7: ='03.04.65'!I110 -> 790085 | F7: ='03.04.65'!J110 -> 140650 | G7: ='03.04.65'!K110 -> 800 | H7: ='03.04.65'!L110 -> 0 | I7: ='03.04.65'!M110 -> 26400 | ... K7: ='03.04.65'!O110 -> 17740 | L7: =B7+C7+D7+E7+F7+G7+H7+I7+J7+K7 -> 1199725
A8: 4 | B8: ='04.04.65'!F148 -> 1950 | C8: ='04.04.65'!G148 -> 178538 | D8: ='04.04.65'!H148 -> 183900 | E8: ='04.04.65'!I148 -> 673195 | F8: ='04.04.65'!J148 -> 217720 | G8: ='04.04.65'!K148 -> 21145 | H8: ='04.04.65'!L148 -> 0 | I8: ='04.04.65'!M148 -> 0 | ... K8: ='04.04.65'!O148 -> 33985 | L8: =B8+C8+D8+E8+F8+G8+H8+I8+J8+K8 -> 1310433
A9: 5 | B9: ='05.04.65'!F111 -> 1850 | C9: ='05.04.65'!G111 -> 2375 | D9: ='05.04.65'!H111 -> 138400 | E9: ='05.04.65'!I111 -> 710775 | F9: ='05.04.65'!J111 -> 142162 | G9: ='05.04.65'!K111 -> 46803 | H9: ='05.04.65'!L111 -> 0 | I9: ='05.04.65'!M111 -> 0 | ... K9: ='05.04.65'!O111 -> 14045 | L9: =B9+C9+D9+E9+F9+G9+H9+I9+J9+K9 -> 1056410
A10: 6 | L10: =B10+C10+D10+E10+F10+G10+H10+I10+J10+K10 -> 0
A11: 7 | B11: ='07.04.65'!F189 -> 17175 | C11: ='07.04.65'!G189 -> 55650 | D11: ='07.04.65'!H189 -> 269000 | E11: ='07.04.65'!I189 -> 1064324 | F11: ='07.04.65'!J189 -> 259775 | G11: ='07.04.65'!K189 -> 54171 | H11: ='07.04.65'!L189 -> 0 | I11: ='07.04.65'!M189 -> 8050 | ... K11: ='07.04.65'!O189 -> 23180 | L11: =B11+C11+D11+E11+F11+G11+H11+I11+J11+K11 -> 1751325
A12: 8 | B12: ='8.04.65'!F129 -> 2669 | C12: ='8.04.65'!G129 -> 42000 | D12: ='8.04.65'!H129 -> 116650 | E12: ='8.04.65'!I129 -> 696315 | F12: ='8.04.65'!J129 -> 132500 | G12: ='8.04.65'!K129 -> 55825 | H12: ='8.04.65'!L129 -> 0 | I12: ='8.04.65'!M129 -> 0 | ... K12: ='8.04.65'!O129 -> 11080 | L12: =B12+C12+D12+E12+F12+G12+H12+I12+J12+K12 -> 1057039
A13: 9 | B13: ='9.04.65'!F92 -> 7507 | C13: ='9.04.65'!G92 -> 4450 | D13: ='9.04.65'!H92 -> 151950 | E13: ='9.04.65'!I92 -> 450720 | F13: ='9.04.65'!J92 -> 192800 | G13: ='9.04.65'!K92 -> 200 | H13: ='9.04.65'!L92 -> 0 | I13: ='9.04.65'!M92 -> 3750 | ... K13: ='9.04.65'!O92 -> 3400 | L13: =B13+C13+D13+E13+F13+G13+H13+I13+J13+K13 -> 814777
A14: 10 | B14: ='10.04.65'!F92 -> 27850 | C14: ='10.04.65'!G92 -> 61450 | D14: ='10.04.65'!H92 -> 121525 | E14: ='10.04.65'!I92 -> 388825 | F14: ='10.04.65'!J92 -> 154550 | G14: ='10.04.65'!K92 -> 38280 | H14: ='10.04.65'!L92 -> 0 | I14: ='10.04.65'!M92 -> 0 | ... K14: ='10.04.65'!O92 -> 34300 | L14: =B14+C14+D14+E14+F14+G14+H14+I14+J14+K14 -> 826780
A15: 11 | C15: ='11.04.65'!G123 -> 148450 | D15: ='11.04.65'!H123 -> 337350 | E15: ='11.04.65'!I123 -> 768325 | F15: ='11.04.65'!J123 -> 207100 | G15: ='11.04.65'!K123 -> 57100 | H15: ='11.04.65'!L123 -> 0 | I15: ='11.04.65'!M123 -> 0 | J15: ='11.04.65'!N123 -> 0 | K15: ='11.04.65'!O123 -> 600 | L15: =B15+C15+D15+E15+F15+G15+H15+I15+J15+K15 -> 1518925
A16: 12 | B16: ='12.04.65'!F96 -> 8100 | C16: ='12.04.65'!G96 -> 20000 | D16: ='12.04.65'!H96 -> 335650 | E16: ='12.04.65'!I96 -> 551430 | F16: ='12.04.65'!J96 -> 171550 | G16: ='12.04.65'!K96 -> 30500 | H16: ='12.04.65'!L96 -> 0 | I16: ='12.04.65'!M96 -> 3250 | ... K16: ='12.04.65'!O96 -> 16800 | L16: =B16+C16+D16+E16+F16+G16+H16+I16+J16+K16 -> 1137280
A17: 13 | L17: =B17+C17+D17+E17+F17+G17+H17+I17+J17+K17 -> 0
A18: 14 | L18: =B18+C18+D18+E18+F18+G18+H18+I18+J18+K18 -> 0
A19: 15 | L19: =B19+C19+D19+E19+F19+G19+H19+I19+J19+K19 -> 0
A20: 16 | B20: ='16.04.65'!F92 -> 3425 | C20: ='16.04.65'!G92 -> 24500 | D20: ='16.04.65'!H92 -> 216765 | E20: ='16.04.65'!I92 -> 516565 | F20: ='16.04.65'!J92 -> 114200 | G20: ='16.04.65'!K92 -> 15025 | H20: ='16.04.65'!L92 -> 0 | I20: ='16.04.65'!M92 -> 0 | ... K20: ='16.04.65'!O92 -> 0 | L20: =B20+C20+D20+E20+F20+G20+H20+I20+J20+K20 -> 890480
A21: 17 | B21: ='17.04.65'!F67 -> 27000 | C21: ='17.04.65'!G67 -> 3200 | D21: ='17.04.65'!H67 -> 118950 | E21: ='17.04.65'!I67 -> 325700 | F21: ='17.04.65'!J67 -> 33584 | G21: ='17.04.65'!K67 -> 6316 | H21: ='17.04.65'!L67 -> 0 | I21: ='17.04.65'!M67 -> 0 | ... K21: ='17.04.65'!O67 -> 0 | L21: =B21+C21+D21+E21+F21+G21+H21+I21+J21+K21 -> 514750
A22: 18 | B22: ='18.04.65'!F105 -> 2225 | C22: ='18.04.65'!G105 -> 123750 | D22: ='18.04.65'!H105 -> 135150 | E22: ='18.04.65'!I105 -> 337730 | F22: ='18.04.65'!J105 -> 138005 | G22: ='18.04.65'!K105 -> 33770 | H22: ='18.04.65'!L105 -> 0 | I22: ='18.04.65'!M105 -> 0 | ... K22: ='18.04.65'!O105 -> 0 | L22: =B22+C22+D22+E22+F22+G22+H22+I22+J22+K22 -> 770630
A23: 19 | B23: ='19.04.65'!F128 -> 1600 | C23: ='19.04.65'!G128 -> 24375 | D23: ='19.04.65'!H128 -> 206550 | E23: ='19.04.65'!I128 -> 785975 | F23: ='19.04.65'!J128 -> 99400 | G23: ='19.04.65'!K128 -> 23090 | H23: ='19.04.65'!L128 -> 0 | I23: ='19.04.65'!M128 -> 5000 | ... K23: ='19.04.65'!O128 -> 0 | L23: =B23+C23+D23+E23+F23+G23+H23+I23+J23+K23 -> 1145990
A24: 20 | B24: ='20.04.65'!F125 -> 8950 | C24: ='20.04.65'!G125 -> 67480 | D24: ='20.04.65'!H125 -> 226300 | E24: ='20.04.65'!I125 -> 817235 | F24: ='20.04.65'!J125 -> 203725 | G24: ='20.04.65'!K125 -> 2950 | H24: ='20.04.65'!L125 -> 0 | I24: ='20.04.65'!M125 -> 0 | ... K24: ='20.04.65'!O125 -> 0 | L24: =B24+C24+D24+E24+F24+G24+H24+I24+J24+K24 -> 1326640
A25: 21 | B25: ='21.04.65'!F117 -> 47900 | C25: ='21.04.65'!G117 -> 101000 | D25: ='21.04.65'!H117 -> 319525 | E25: ='21.04.65'!I117 -> 451445 | F25: ='21.04.65'!J117 -> 160125 | G25: ='21.04.65'!K117 -> 25000 | H25: ='21.04.65'!L117 -> 0 | I25: ='21.04.65'!M117 -> 6050 | ... K25: ='21.04.65'!O117 -> 0 | L25: =B25+C25+D25+E25+F25+G25+H25+I25+J25+K25 -> 1111045
A26: 22 | B26: ='22.04.65'!F112 -> 0 | C26: ='22.04.65'!G112 -> 27400 | D26: ='22.04.65'!H112 -> 530350 | E26: ='22.04.65'!I112 -> 708265 | F26: ='22.04.65'!J112 -> 381525 | G26: ='22.04.65'!K112 -> 8750 | H26: ='22.04.65'!L112 -> 0 | I26: ='22.04.65'!M112 -> 0 | ... K26: ='22.04.65'!O112 -> 0 | L26: =B26+C26+D26+E26+F26+G26+H26+I26+J26+K26 -> 1656290
A27: 23 | B27: ='23.04.65'!F118 -> 27250 | C27: ='23.04.65'!G118 -> 41555 | D27: ='23.04.65'!H118 -> 393150 | E27: ='23.04.65'!I118 -> 582170 | F27: ='23.04.65'!J118 -> 162272 | G27: ='23.04.65'!K118 -> 31638 | H27: ='23.04.65'!L118 -> 0 | I27: ='23.04.65'!M118 -> 350 | ... K27: ='23.04.65'!O118 -> 0 | L27: =B27+C27+D27+E27+F27+G27+H27+I27+J27+K27 -> 1238385
A28: 24 | B28: ='24.04.65'!F61 -> 36664 | C28: ='24.04.65'!G61 -> 0 | D28: ='24.04.65'!H61 -> 175500 | E28: ='24.04.65'!I61 -> 414420 | F28: ='24.04.65'!J61 -> 84705 | G28: ='24.04.65'!K61 -> 10700 | H28: ='24.04.65'!L61 -> 0 | I28: ='24.04.65'!M61 -> 10000 | ... K28: ='24.04.65'!O61 -> 0 | L28: =B28+C28+D28+E28+F28+G28+H28+I28+J28+K28 -> 731989
A29: 25 | B29: ='25.04.65'!F153 -> 10200 | C29: ='25.04.65'!G153 -> 23350 | D29: ='25.04.65'!H153 -> 339525 | E29: ='25.04.65'!I153 -> 623085 | F29: ='25.04.65'!J153 -> 269686 | G29: ='25.04.65'!K153 -> 10959 | H29: ='25.04.65'!L153 -> 0 | I29: ='25.04.65'!M153 -> 2600 | ... K29: ='25.04.65'!O153 -> 0 | L29: =B29+C29+D29+E29+F29+G29+H29+I29+J29+K29 -> 1279405
A30: 26 | B30: ='26.04.65'!F126 -> 7350 | C30: ='26.04.65'!G126 -> 97450 | D30: ='26.04.65'!H126 -> 241500 | E30: ='26.04.65'!I126 -> 553575 | F30: ='26.04.65'!J126 -> 239905 | G30: ='26.04.65'!K126 -> 81400 | H30: ='26.04.65'!L126 -> 0 | I30: ='26.04.65'!M126 -> 0 | ... K30: ='26.04.65'!O126 -> 0 | L30: =B30+C30+D30+E30+F30+G30+H30+I30+J30+K30 -> 1221180
A31: 27 | B31: ='27.04.65'!F90 -> 20100 | C31: ='27.04.65'!G90 -> 16650 | D31: ='27.04.65'!H90 -> 297825 | E31: ='27.04.65'!I90 -> 380048 | F31: ='27.04.65'!J90 -> 148995 | G31: ='27.04.65'!K90 -> 500 | H31: ='27.04.65'!L90 -> 0 | I31: ='27.04.65'!M90 -> 34600 | ... K31: ='27.04.65'!O90 -> 0 | L31: =B31+C31+D31+E31+F31+G31+H31+I31+J31+K31 -> 898718
A32: 28 | B32: ='28.04.65'!F103 -> 2625 | C32: ='28.04.65'!G103 -> 16150 | D32: ='28.04.65'!H103 -> 704075 | E32: ='28.04.65'!I103 -> 400395 | F32: ='28.04.65'!J103 -> 109740 | G32: ='28.04.65'!K103 -> 0 | H32: ='28.04.65'!L103 -> 0 | I32: ='28.04.65'!M103 -> 0 | ... K32: ='28.04.65'!O103 -> 0 | L32: =B32+C32+D32+E32+F32+G32+H32+I32+J32+K32 -> 1232985
A33: 29 | B33: ='29.04.65'!F127 -> 800 | C33: ='29.04.65'!G127 -> 300900 | D33: ='29.04.65'!H127 -> 496625 | E33: ='29.04.65'!I127 -> 629208 | F33: ='29.04.65'!J127 -> 148430 | G33: ='29.04.65'!K127 -> 14927 | H33: ='29.04.65'!L127 -> 0 | I33: ='29.04.65'!M127 -> 0 | ... K33: ='29.04.65'!O127 -> 0 | L33: =B33+C33+D33+E33+F33+G33+H33+I33+J33+K33 -> 1590890
A34: 30 | B34: ='30.04.65'!F137 -> 0 | C34: ='30.04.65'!G137 -> 35000 | D34: ='30.04.65'!H137 -> 803650 | E34: ='30.04.65'!I137 -> 637890 | F34: ='30.04.65'!J137 -> 190425 | G34: ='30.04.65'!K137 -> 19670 | H34: ='30.04.65'!L137 -> 0 | I34: ='30.04.65'!M137 -> 0 | ... K34: ='30.04.65'!O137 -> 0 | L34: =B34+C34+D34+E34+F34+G34+H34+I34+J34+K34 -> 1686635
A35: 31 | L35: =B35+C35+D35+E35+F35+G35+J35+K35 -> 0
A36: TOTAL | B36: =SUM(B3:B35) -> 263790 | C36: =SUM(C3:C35) -> 1484473 | D36: =SUM(D3:D35) -> 7379455 | E36: =SUM(E3:E35) -> 15171106 | F36: =SUM(F3:F35) -> 4446709 | G36: =SUM(G3:G35) -> 628459 | H36: =SUM(H3:H35) -> 0 | I36: =SUM(I3:I35) -> 100050 | ... L36: =SUM(L3:L35) -> 29660911

Sheet 31-2.04.65
A1: DAILY SALE 31-2 MAY 2022
A2: NO | B2: วันที่ | C2: เลขออเดอร์ | D2: รหัส | E2: Name | F2: Payment | R2: CS ผู้คีย์บิล
F3: Cash | G3: Credit Card | I3: Tranfer Money | K3: E-WALLET | L3: Paypal | M3: qr paymet | N3: หักคอม | O3: ARP | P3: ยอดในระบบ | Q3: ผลต่าง
G4: Front Office | H4: Online | I4: KBANK | J4: KTB
A5: 1 | Q5: =SUM(F5+G5+H5+I5+J5+K5+L5+N5+O5-P5) -> 0
A6: 2 | Q6: =SUM(F6+G6+H6+I6+J6+K6+L6+N6+O6-P6) -> 0
A7: 3 | Q7: =SUM(F7+G7+H7+I7+J7+K7+L7+N7+O7-P7) -> 0
A8: 4 | Q8: =SUM(F8+G8+H8+I8+J8+K8+L8+N8+O8-P8) -> 0
A9: 5 | Q9: =SUM(F9+G9+H9+I9+J9+K9+L9+N9+O9-P9) -> 0
A10: 6 | Q10: =SUM(F10+G10+H10+I10+J10+K10+L10+N10+O10-P10) -> 0
A11: 7 | Q11: =SUM(F11+G11+H11+I11+J11+K11+L11+N11+O11-P11) -> 0
A12: 8 | Q12: =SUM(F12+G12+H12+I12+J12+K12+L12+N12+O12-P12) -> 0
A13: 9 | Q13: =SUM(F13+G13+H13+I13+J13+K13+L13+N13+O13-P13) -> 0
A14: 10 | Q14: =SUM(F14+G14+H14+I14+J14+K14+L14+N14+O14-P14) -> 0
A15: 11 | Q15: =SUM(F15+G15+H15+I15+J15+K15+L15+N15+O15-P15) -> 0
A16: 12 | Q16: =SUM(F16+G16+H16+I16+J16+K16+L16+N16+O16-P16) -> 0
... A190: 187 | Q190: =SUM(F190+G190+H190+I190+J190+K190+L190+N190+O190-P190) -> 0
F191: =SUM(F5:F189) -> 0 | G191: =SUM(G4:G190) -> 0 | H191: =SUM(H4:H190) -> 0 | I191: =SUM(I4:I190) -> 0 | J191: =SUM(J4:J190) -> 0 | K191: =SUM(K4:K190) -> 0 | L191: =SUM(L4:L190) -> 0 | M191: =SUM(M4:M190) -> 0 | N191: =SUM(N4:N190) -> 0 | O191: =SUM(O4:O190) -> 0 | P191: =SUM(P5:P190) -> 0 | Q191: =SUM(Q5:Q190) -> 0
F192: =F191+G191+H191+I191+J191+K191+L191+M191+N191+O191 -> 0
F199: า

Sheet 03.04.65
A1: DAILY SALE 3 APRIL 2022
A2: NO | B2: วันที่ | C2: เลขออเดอร์ | D2: รหัส | E2: Name | F2: Payment | R2: CS ผู้คีย์บิล
F3: Cash | G3: Credit Card | I3: Tranfer Money | K3: E-WALLET | L3: Paypal | M3: qr paymet | N3: หักคอม | O3: ARP | P3: ยอดในระบบ | Q3: ผลต่าง
G4: Front Office | H4: Online | I4: KBANK | J4: KTB
A5: 1 | B5: 44653 | C5: STHBKK012204000203 | D5: 66012 | E5: นางสาว พรทิพย์&#8203;วงษ์ชัย | I5: 6400 | P5: 6400 | Q5: =SUM(F5+G5+H5+I5+J5+K5+L5+M5+N5+O5-P5) -> 0 | R5: bkk-aoeng
A6: 2 | B6: 44653 | C6: STHBKK012204000204 | D6: 67687 | E6: นางสาว วธิดา ไตรรัตน์ | I6: 2500 | P6: 2500 | Q6: =SUM(F6+G6+H6+I6+J6+K6+L6+M6+N6+O6-P6) -> 0 | R6: bkk-aoeng
A7: 3 | B7: 44654 | C7: STHBKK012204000207 | D7: 30895 | E7: นาย สิปปภาส โรจนวสุธร | J7: 350 | P7: 350 | Q7: =SUM(F7+G7+H7+I7+J7+K7+L7+M7+N7+O7-P7) -> 0 | R7: bkk-aoeng
A8: 4 | B8: 44654 | C8: STHBKK012204000208 | D8: 30895 | E8: นาย สิปปภาส โรจนวสุธร | J8: 3000 | P8: 3000 | Q8: =SUM(F8+G8+H8+I8+J8+K8+L8+M8+N8+O8-P8) -> 0 | R8: bkk-aoeng
A9: 5 | B9: 44654 | C9: STHBKK012204000209 | D9: 48631 | E9: ดร. โนรี เต๊ะหละ | I9: 20200 | P9: 20200 | Q9: =SUM(F9+G9+H9+I9+J9+K9+L9+M9+N9+O9-P9) -> 0 | R9: bkk-aoeng
A10: 6 | B10: 44654 | C10: STHBKK012204000210 | D10: 45193 | E10: นาง ศิลา สงอาจินต์ | I10: 39780 | P10: 39780 | Q10: =SUM(F10+G10+H10+I10+J10+K10+L10+M10+N10+O10-P10) -> 0 | R10: BKK-Neng
A11: 7 | B11: 44654 | C11: STHBKK012204000212 | D11: 58752 | E11: นาย คำรณ สะอาดเอี่ยม | I11: 300 | P11: 300 | Q11: =SUM(F11+G11+H11+I11+J11+K11+L11+M11+N11+O11-P11) -> 0 | R11: bkk-aoeng
A12: 8 | B12: 44654 | C12: STHBKK012204000213 | D12: 58823 | E12: นาย อนพันธ์ เมธาพรสูทิวัส | I12: 300 | P12: 300 | Q12: =SUM(F12+G12+H12+I12+J12+K12+L12+M12+N12+O12-P12) -> 0 | R12: bkk-aoeng
A13: 9 | B13: 44654 | C13: STHBKK012204000214 | D13: 61386 | E13: นาย ปรียะนนย์ ภูนารี | I13: 300 | P13: 300 | Q13: =SUM(F13+G13+H13+I13+J13+K13+L13+M13+N13+O13-P13) -> 0 | R13: bkk-aoeng
A14: 10 | B14: 44654 | C14: STHBKK012204000215 | D14: 61898 | E14: นาย อำนาจ เสือสูงเนิน | I14: 300 | P14: 300 | Q14: =SUM(F14+G14+H14+I14+J14+K14+L14+M14+N14+O14-P14) -> 0 | R14: bkk-aoeng
A15: 11 | B15: 44654 | C15: STHBKK012204000216 | D15: 62582 | E15: นาย สุพจน์ สัตตบุษ | I15: 300 | P15: 300 | Q15: =SUM(F15+G15+H15+I15+J15+K15+L15+M15+N15+O15-P15) -> 0 | R15: bkk-aoeng
A16: 12 | B16: 44654 | C16: STHBKK012204000217 | D16: 45193 | E16: นาง ศิลา สงอาจินต์ | I16: 10000 | P16: 10000 | Q16: =SUM(F16+G16+H16+I16+J16+K16+L16+M16+N16+O16-P16) -> 0 | R16: BKK-Neng
A17: 13 | B17: 44654 | C17: STHBKK012204000218 | D17: 63679 | E17: นาย วิเชียร ดีบุกคำ | I17: 300 | P17: 300 | Q17: =SUM(F17+G17+H17+I17+J17+K17+L17+M17+N17+O17-P17) -> 0 | R17: bkk-aoeng
A18: 14 | B18: 44654 | C18: STHBKK012204000219 | D18: 63869 | E18: นาย สุชาติ ชาติขุนทด | I18: 300 | P18: 300 | Q18: =SUM(F18+G18+H18+I18+J18+K18+L18+M18+N18+O18-P18) -> 0 | R18: bkk-aoeng
A19: 15 | B19: 44654 | C19: STHBKK012204000220 | D19: 59662 | E19: นาย วีระพล เรืองมณี | I19: 300 | P19: 300 | Q19: =SUM(F19+G19+H19+I19+J19+K19+L19+M19+N19+O19-P19) -> 0 | R19: bkk-aoeng
A20: 16 | B20: 44654 | C20: STHBKK012204000221 | D20: 68318 | E20: นาย อภิสิทธิ์ สุขสบาย | I20: 300 | P20: 300 | Q20: =SUM(F20+G20+H20+I20+J20+K20+L20+M20+N20+O20-P20) -> 0 | R20: bkk-aoeng
A21: 17 | B21: 44654 | C21: STHBKK012204000222 | D21: 62941 | E21: นางสาว สุคนธมาส ฟองสมบูรณ์ | I21: 300 | P21: 300 | Q21: =SUM(F21+G21+H21+I21+J21+K21+L21+M21+N21+O21-P21) -> 0 | R21: bkk-aoeng
A22: 18 | B22: 44654 | C22: STHBKK012204000223 | D22: 54937 | E22: นาย ทวี เกษี | J22: 2750 | P22: 2750 | Q22: =SUM(F22+G22+H22+I22+J22+K22+L22+M22+N22+O22-P22) -> 0 | R22: bkk-aoeng
A23: 19 | B23: 44654 | C23: STHBKK012204000225 | D23: 55992 | E23: นาย จักรพงศ์ เพชรเหลี่ยม | I23: 350 | P23: 350 | Q23: =SUM(F23+G23+H23+I23+J23+K23+L23+M23+N23+O23-P23) -> 0 | R23: bkk-aoeng
A24: 20 | B24: 44654 | C24: STHBKK012204000226 | D24: 51406 | E24: บริษัท สวนสุข จำกัด(สำนักงานใหญ่) | I24: 8550 | P24: 8550 | Q24: =SUM(F24+G24+H24+I24+J24+K24+L24+M24+N24+O24-P24) -> 0 | R24: bkk-aoeng
A25: 21 | B25: 44654 | C25: STHBKK012204000227 | D25: 68797 | E25: นาย สนั่น ผุกผา | I25: 27000 | P25: 27000 | Q25: =SUM(F25+G25+H25+I25+J25+K25+L25+M25+N25+O25-P25) -> 0 | R25: PoonBKK
A26: 22 | B26: 44654 | C26: STHBKK012204000229 | D26: 35245 | E26: ร้าน first beautiful | I26: 226000 | P26: 226000 | Q26: =SUM(F26+G26+H26+I26+J26+K26+L26+M26+N26+O26-P26) -> 0 | R26: PoonBKK
A27: 23 | B27: 44654 | C27: STHBKK012204000230 | D27: 52396 | E27: นาง รัตนกร ไม้แดง | J27: 5000 | P27: 5000 | Q27: =SUM(F27+G27+H27+I27+J27+K27+L27+M27+N27+O27-P27) -> 0 | R27: BKK-Neng
A28: 24 | B28: 44654 | C28: STHBKK012204000231 | D28: 54242 | E28: นาย ณัฐพล ไม้แดง | J28: 5000 | P28: 5000 | Q28: =SUM(F28+G28+H28+I28+J28+K28+L28+M28+N28+O28-P28) -> 0 | R28: BKK-Neng
A29: 25 | B29: 44654 | C29: STHBKK012204000232 | D29: 10001 | E29: บริษัท สว่างทรัพย์ จำกัด (สำนักงานใหญ่) | I29: 350 | P29: 350 | Q29: =SUM(F29+G29+H29+I29+J29+K29+L29+M29+N29+O29-P29) -> 0 | R29: PoonBKK
A30: 26 | B30: 44654 | C30: STHBKK012204000233 | D30: 52808 | E30: นาย จตุรเทพ ไม้แดง | J30: 7650 | P30: 7650 | Q30: =SUM(F30+G30+H30+I30+J30+K30+L30+M30+N30+O30-P30) -> 0 | R30: BKK-Neng
A31: 27 | B31: 44654 | C31: STHBKK012204000234 | D31: 51743 | E31: นาย เลิศวรรธน์ ศรีภิรมย์ | J31: 5000 | P31: 5000 | Q31: =SUM(F31+G31+H31+I31+J31+K31+L31+M31+N31+O31-P31) -> 0 | R31: bkk-aoeng
A32: 28 | B32: 44654 | C32: STHBKK012204000236 | D32: 51976 | E32: นาง วรัทยา จันทร์ชื่น | J32: 5000 | P32: 5000 | Q32: =SUM(F32+G32+H32+I32+J32+K32+L32+M32+N32+O32-P32) -> 0 | R32: bkk-aoeng
A33: 29 | B33: 44654 | C33: STHBKK012204000237 | D33: 51939 | E33: บริษัท รินทร์รฐา กรุ๊ป จำกัด(สำนักงานใหญ่) | I33: 19350 | P33: 19350 | Q33: =SUM(F33+G33+H33+I33+J33+K33+L33+M33+N33+O33-P33) -> 0 | R33: bkk-aoeng
A34: 30 | B34: 44654 | C34: STHBKK012204000238 | D34: 48343 | E34: นาย บรรจง ปุยอบ | I34: 10125 | P34: 10125 | Q34: =SUM(F34+G34+H34+I34+J34+K34+L34+M34+N34+O34-P34) -> 0 | R34: BKK-Neng
A35: 31 | B35: 44654 | C35: STHBKK012204000240 | D35: 50173 | E35: นาย ธนภัทร อยู่คำ | J35: 3950 | P35: 3950 | Q35: =SUM(F35+G35+H35+I35+J35+K35+L35+M35+N35+O35-P35) -> 0 | R35: bkk-aoeng
A36: 32 | B36: 44654 | C36: STHBKK012204000241 | D36: 51876 | E36: นางสาว จิราภรณ์ เขาทอง | I36: 52200 | P36: 52200 | Q36: =SUM(F36+G36+H36+I36+J36+K36+L36+M36+N36+O36-P36) -> 0 | R36: bkk-aoeng
A37: 33 | B37: 44654 | C37: STHBKK012204000242 | D37: 64951 | E37: นาง ณิชารีย์ บุญญารัตน์สถาพร | I37: 10000 | P37: 10000 | Q37: =SUM(F37+G37+H37+I37+J37+K37+L37+M37+N37+O37-P37) -> 0 | R37: BKK-Neng
A38: 34 | B38: 44654 | C38: STHBKK012204000247 | D38: 62809 | E38: นางสาว วรารัตน์ ฤกษ์ศรี | I38: 350 | P38: 350 | Q38: =SUM(F38+G38+H38+I38+J38+K38+L38+M38+N38+O38-P38) -> 0 | R38: BKK-Neng
A39: 35 | B39: 44654 | C39: STHBKK012204000250 | D39: 60282 | E39: นาง ณฐมน เสมือนคิด | M39: 300 | P39: 300 | Q39: =SUM(F39+G39+H39+I39+J39+K39+L39+M39+N39+O39-P39) -> 0 | R39: PoonBKK
A40: 36 | B40: 44654 | C40: STHBKK012204000251 | D40: 10320 | E40: บริษัท รีโวเด็ค จำกัด (สำนักงานใหญ่) | I40: 34100 | P40: 34100 | Q40: =SUM(F40+G40+H40+I40+J40+K40+L40+M40+N40+O40-P40) -> 0 | R40: bkk-aoeng
...

Sheet 04.04.65
A1: DAILY SALE 4 APRIL 2022
A2: NO | B2: วันที่ | C2: เลขออเดอร์ | D2: รหัส | E2: Name | F2: Payment | R2: CS ผู้คีย์บิล
F3: Cash | G3: Credit Card | I3: Tranfer Money | K3: E-WALLET | L3: Paypal | M3: qr paymet | N3: หักคอม | O3: ARP | P3: ยอดในระบบ | Q3: ผลต่าง
G4: Front Office | H4: Online | I4: KBANK | J4: KTB
A5: 1 | B5: 44654 | C5: STHBKK012204000330 | D5: 35220 | E5: นาย ดัสนีย์​ เจะ​เลาะ​ | G5: 0 | P5: 15000 | Q5: =SUM(F5+G5+H5+I5+J5+K5+L5+M5+N5+O5-P5) -> -15000 | R5: bkk-aoeng
A6: 2 | B6: 44655 | C6: STHBKK012204000336 | D6: 59904 | E6: นาย สุรทัศน์ เกไธสร | I6: 5000 | P6: 5000 | Q6: =SUM(F6+G6+H6+I6+J6+K6+L6+M6+N6+O6-P6) -> 0 | R6: bkk-aoeng
A7: 3 | B7: 44655 | C7: STHBKK012204000337 | D7: 45193 | E7: นาง ศิลา สงอาจินต์ | I7: 10200 | P7: 10200 | Q7: =SUM(F7+G7+H7+I7+J7+K7+L7+M7+N7+O7-P7) -> 0 | R7: Katae BKK
A8: 4 | B8: 44655 | C8: STHBKK012204000338 | D8: 36555 | E8: นางสาว พิมพ์มาดา เงางาม | I8: 8750 | P8: 8750 | Q8: =SUM(F8+G8+H8+I8+J8+K8+L8+M8+N8+O8-P8) -> 0 | R8: bkk-aoeng
A9: 5 | B9: 44655 | C9: STHBKK012204000339 | D9: 48234 | E9: นาย กมล อินอ่อน | I9: 3900 | P9: 3900 | Q9: =SUM(F9+G9+H9+I9+J9+K9+L9+M9+N9+O9-P9) -> 0 | R9: Katae BKK
A10: 6 | B10: 44655 | C10: STHBKK012204000341 | D10: 14329 | E10: นาย มงคล เพ็งเคียน | I10: 2500 | P10: 2500 | Q10: =SUM(F10+G10+H10+I10+J10+K10+L10+M10+N10+O10-P10) -> 0 | R10: bkk-aoeng
A11: 7 | B11: 44655 | C11: STHBKK012204000342 | D11: 65111 | E11: นางสาว พิชญ์ชิชา สุดทิพย์รัสกร | F11: 300 | P11: 300 | Q11: =SUM(F11+G11+H11+I11+J11+K11+L11+M11+N11+O11-P11) -> 0 | R11: PoonBKK
A12: 8 | B12: 44655 | C12: STHBKK012204000344 | D12: 55366 | E12: นาย อัฒรพงษ์ กาญจนโกมล | J12: 1900 | P12: 1900 | Q12: =SUM(F12+G12+H12+I12+J12+K12+L12+M12+N12+O12-P12) -> 0 | R12: PoonBKK
A13: 9 | B13: 44655 | C13: STHBKK012204000345 | D13: 51939 | E13: บริษัท รินทร์รฐา กรุ๊ป จำกัด(สำนักงานใหญ่) | I13: 13900 | P13: 13900 | Q13: =SUM(F13+G13+H13+I13+J13+K13+L13+M13+N13+O13-P13) -> 0 | R13: bkk-nee
A14: 10 | B14: 44655 | C14: STHBKK012204000346 | D14: 68990 | E14: นางสาว สมคิด พันธ์คำ | J14: 500 | P14: 500 | Q14: =SUM(F14+G14+H14+I14+J14+K14+L14+M14+N14+O14-P14) -> 0 | R14: PoonBKK
A15: 11 | B15: 44655 | C15: STHBKK012204000347 | D15: 25650 | E15: นาง ศศกร อมตวงษ์ | K15: 500 | P15: 500 | Q15: =SUM(F15+G15+H15+I15+J15+K15+L15+M15+N15+O15-P15) -> 0 | R15: Katae BKK
A16: 12 | B16: 44655 | C16: STHBKK012204000348 | D16: 69075 | E16: นางสาว แก้ว วงค์คำ | J16: 500 | P16: 500 | Q16: =SUM(F16+G16+H16+I16+J16+K16+L16+M16+N16+O16-P16) -> 0 | R16: PoonBKK
A17: 13 | B17: 44655 | C17: STHBKK012204000349 | D17: 63158 | E17: นาย ลภชัย จินดารัตน์ | J17: 500 | P17: 500 | Q17: =SUM(F17+G17+H17+I17+J17+K17+L17+M17+N17+O17-P17) -> 0 | R17: PoonBKK
A18: 14 | B18: 44655 | C18: STHBKK012204000350 | D18: 69106 | E18: นาย วิฑูรย์ อุรุวรรณ | J18: 500 | P18: 500 | Q18: =SUM(F18+G18+H18+I18+J18+K18+L18+M18+N18+O18-P18) -> 0 | R18: PoonBKK
A19: 15 | B19: 44655 | C19: STHBKK012204000351 | D19: 69058 | E19: นางสาว บัว อุ่มครบุรี | J19: 500 | P19: 500 | Q19: =SUM(F19+G19+H19+I19+J19+K19+L19+M19+N19+O19-P19) -> 0 | R19: PoonBKK
A20: 16 | B20: 44655 | C20: STHBKK012204000352 | D20: 68810 | E20: นางสาว ปานระพี สืบกระแสร์ | J20: 500 | P20: 500 | Q20: =SUM(F20+G20+H20+I20+J20+K20+L20+M20+N20+O20-P20) -> 0 | R20: PoonBKK
A21: 17 | B21: 44655 | C21: STHBKK012204000353 | D21: 69109 | E21: นางสาว กาญจนาพร ด้วงเงิน | J21: 500 | P21: 500 | Q21: =SUM(F21+G21+H21+I21+J21+K21+L21+M21+N21+O21-P21) -> 0 | R21: PoonBKK
A22: 18 | B22: 44655 | C22: STHBKK012204000354 | D22: 68987 | E22: นางสาว สมพร บริสุทธิ์ | J22: 500 | P22: 500 | Q22: =SUM(F22+G22+H22+I22+J22+K22+L22+M22+N22+O22-P22) -> 0 | R22: PoonBKK
A23: 19 | B23: 44655 | C23: STHBKK012204000355 | D23: 34941 | E23: นาง วรางค์ศิริ ภัทรเดชกวีทิพย์ | J23: 500 | P23: 500 | Q23: =SUM(F23+G23+H23+I23+J23+K23+L23+M23+N23+O23-P23) -> 0 | R23: PoonBKK
A24: 20 | B24: 44655 | C24: STHBKK012204000356 | D24: 68417 | E24: นาย ศิริวัฒน์ ศิริวงศ์ศาล | J24: 500 | P24: 500 | Q24: =SUM(F24+G24+H24+I24+J24+K24+L24+M24+N24+O24-P24) -> 0 | R24: PoonBKK
A25: 21 | B25: 44655 | C25: STHBKK012204000357 | D25: 68844 | E25: นาง ปิ่นคำ ประดิษฐ์ | J25: 500 | P25: 500 | Q25: =SUM(F25+G25+H25+I25+J25+K25+L25+M25+N25+O25-P25) -> 0 | R25: PoonBKK
A26: 22 | B26: 44655 | C26: STHBKK012204000358 | D26: 68587 | E26: นาย บรรพตต์ ภวะวิจารณ์ | J26: 500 | P26: 500 | Q26: =SUM(F26+G26+H26+I26+J26+K26+L26+M26+N26+O26-P26) -> 0 | R26: PoonBKK
A27: 23 | B27: 44655 | C27: STHBKK012204000362 | D27: 58858 | E27: นางสาว วัลยาลักษณ์ เกษมอัครธำรง | I27: 350 | P27: 350 | Q27: =SUM(F27+G27+H27+I27+J27+K27+L27+M27+N27+O27-P27) -> 0 | R27: bkk-aoeng
A28: 24 | B28: 44655 | C28: STHBKK012204000364 | D28: 52032 | E28: นางสาว กาญจนา จองเกียรติ์ | I28: 350 | P28: 350 | Q28: =SUM(F28+G28+H28+I28+J28+K28+L28+M28+N28+O28-P28) -> 0 | R28: PoonBKK
A29: 25 | B29: 44655 | C29: STHBKK012204000365 | D29: 52206 | E29: นาย ภูวกร บวรฉัตรชาตรี | I29: 30840 | P29: 30840 | Q29: =SUM(F29+G29+H29+I29+J29+K29+L29+M29+N29+O29-P29) -> 0 | R29: bkk-aoeng
A30: 26 | B30: 44655 | C30: STHBKK012204000366 | D30: 67410 | E30: นาย ไช จอมมะนีวง | I30: 10000 | P30: 10000 | Q30: =SUM(F30+G30+H30+I30+J30+K30+L30+M30+N30+O30-P30) -> 0 | R30: PoonBKK
A31: 27 | B31: 44655 | C31: STHBKK012204000368 | D31: 36928 | E31: นาง ฐานมญ ชลคีรี | J31: 3750 | P31: 3750 | Q31: =SUM(F31+G31+H31+I31+J31+K31+L31+M31+N31+O31-P31) -> 0 | R31: PoonBKK
A32: 28 | B32: 44655 | C32: STHBKK012204000369 | D32: 55162 | E32: นางสาว สุพัตรา กันเฉย | J32: 27500 | P32: 27500 | Q32: =SUM(F32+G32+H32+I32+J32+K32+L32+M32+N32+O32-P32) -> 0 | R32: bkk-aoeng
A33: 29 | B33: 44655 | C33: STHBKK012204000370 | D33: 52669 | E33: บริษัท โคบาราเอฟโวลูชั่น (ประเทศไทย)จำกัด | G33: 15000 | P33: 15000 | Q33: =SUM(F33+G33+H33+I33+J33+K33+L33+M33+N33+O33-P33) -> 0 | R33: bkk-aoeng
A34: 30 | B34: 44655 | C34: STHBKK012204000372 | D34: 51876 | E34: นางสาว จิราภรณ์ เขาทอง | I34: 30000 | P34: 30000 | Q34: =SUM(F34+G34+H34+I34+J34+K34+L34+M34+N34+O34-P34) -> 0 | R34: bkk-aoeng
A35: 31 | B35: 44655 | C35: STHBKK012204000373 | D35: 55388 | E35: นาย จรัญ กอบธัญกรณ์ | I35: 2650 | P35: 2650 | Q35: =SUM(F35+G35+H35+I35+J35+K35+L35+M35+N35+O35-P35) -> 0 | R35: bkk-aoeng
A36: 32 | B36: 44655 | C36: STHBKK012204000374 | D36: 50613 | E36: นางสาว นฤมล พุ่มแสง | J36: 2650 | P36: 2650 | Q36: =SUM(F36+G36+H36+I36+J36+K36+L36+M36+N36+O36-P36) -> 0 | R36: bkk-aoeng
A37: 33 | B37: 44655 | C37: STHBKK012204000375 | D37: 51069 | E37: นาย วีรกร พงษ์วัน | I37: 5200 | P37: 5200 | Q37: =SUM(F37+G37+H37+I37+J37+K37+L37+M37+N37+O37-P37) -> 0 | R37: Katae BKK
A38: 34 | B38: 44655 | C38: STHBKK012204000377 | D38: 53283 | E38: นางสาว กนกวรรณ โต๊ะดี | I38: 5200 | P38: 5200 | Q38: =SUM(F38+G38+H38+I38+J38+K38+L38+M38+N38+O38-P38) -> 0 | R38: bkk-aoeng
A39: 35 | B39: 44655 | C39: STHBKK012204000378 | D39: 42060 | E39: เจษฎาภรณ์ วิลัยกุล | H39: 3750 | P39: 3750 | Q39: =SUM(F39+G39+H39+I39+J39+K39+L39+M39+N39+O39-P39) -> 0 | R39: PoonBKK
A40: 36 | B40: 44655 | C40: STHBKK012204000379 | D40: 42046 | E40: นาย ธนกร อภัยพงศ์ | H40: 5275 | P40: 5275 | Q40: =SUM(F40+G40+H40+I40+J40+K40+L40+M40+N40+O40-P40) -> 0 | R40: PoonBKK
...

Sheet 05.04.65
A1: DAILY SALE 5 APRIL 2022
A2: NO | B2: วันที่ | C2: เลขออเดอร์ | D2: รหัส | E2: Name | F2: Payment | R2: CS ผู้คีย์บิล
F3: Cash | G3: Credit Card | I3: Tranfer Money | K3: E-WALLET | L3: Paypal | M3: qr paymet | N3: หักคอม | O3: ARP | P3: ยอดในระบบ | Q3: ผลต่าง
G4: Front Office | H4: Online | I4: KBANK | J4: KTB
A5: 1 | B5: 44655 | C5: STHBKK012204000519 | D5: 41826 | E5: สมใจ มั่นคง | G5: 600 | P5: 600 | Q5: =SUM(F5+G5+H5+I5+J5+K5+L5+M5+N5+O5-P5) -> 0 | R5: PoonBKK
A6: 2 | B6: 44656 | C6: STHBKK012204000520 | D6: 10320 | E6: บริษัท รีโวเด็ค จำกัด (สำนักงานใหญ่) | I6: 350 | P6: 350 | Q6: =SUM(F6+G6+H6+I6+J6+K6+L6+M6+N6+O6-P6) -> 0 | R6: Katae BKK
A7: 3 | B7: 44656 | C7: STHBKK012204000523 | D7: 50173 | E7: นาย ธนภัทร อยู่คำ | I7: 2650 | P7: 2650 | Q7: =SUM(F7+G7+H7+I7+J7+K7+L7+M7+N7+O7-P7) -> 0 | R7: Katae BKK
A8: 4 | B8: 44656 | C8: STHBKK012204000525 | D8: 51939 | E8: บริษัท รินทร์รฐา กรุ๊ป จำกัด(สำนักงานใหญ่) | I8: 11400 | P8: 11400 | Q8: =SUM(F8+G8+H8+I8+J8+K8+L8+M8+N8+O8-P8) -> 0 | R8: Katae BKK
A9: 5 | B9: 44656 | C9: STHBKK012204000528 | D9: 50854 | E9: นาง วันดี คำไพ | I9: 300 | P9: 300 | Q9: =SUM(F9+G9+H9+I9+J9+K9+L9+M9+N9+O9-P9) -> 0 | R9: BKK-Neng
A10: 6 | B10: 44656 | C10: STHBKK012204000529 | D10: 49777 | E10: นาง ภัทฐิชา พุ่มพุก | J10: 5000 | P10: 5000 | Q10: =SUM(F10+G10+H10+I10+J10+K10+L10+M10+N10+O10-P10) -> 0 | R10: Katae BKK
A11: 7 | B11: 44656 | C11: STHBKK012204000531 | D11: 46778 | E11: นาย ปรีชา แก้วโกถม | J11: 7500 | P11: 7500 | Q11: =SUM(F11+G11+H11+I11+J11+K11+L11+M11+N11+O11-P11) -> 0 | R11: Katae BKK
A12: 8 | B12: 44656 | C12: STHBKK012204000533 | D12: 46778 | E12: นาย ปรีชา แก้วโกถม | J12: 1250 | P12: 1250 | Q12: =SUM(F12+G12+H12+I12+J12+K12+L12+M12+N12+O12-P12) -> 0 | R12: Katae BKK
A13: 9 | B13: 44656 | C13: STHBKK012204000535 | D13: 69160 | E13: นางสาว ณัชภวิกา ประชาเชษฐ์ | I13: 27000 | P13: 27000 | Q13: =SUM(F13+G13+H13+I13+J13+K13+L13+M13+N13+O13-P13) -> 0 | R13: PoonBKK
A14: 10 | B14: 44656 | C14: STHBKK012204000536 | D14: 36928 | E14: นาง ฐานมญ ชลคีรี | K14: 11025 | P14: 11025 | Q14: =SUM(F14+G14+H14+I14+J14+K14+L14+M14+N14+O14-P14) -> 0 | R14: lFrAmEl
A15: 11 | B15: 44656 | C15: STHBKK012204000538 | D15: 48052 | E15: นาง นภาไพลิน กาละวันต์ | I15: 5000 | P15: 5000 | Q15: =SUM(F15+G15+H15+I15+J15+K15+L15+M15+N15+O15-P15) -> 0 | R15: Katae BKK
A16: 12 | B16: 44656 | C16: STHBKK012204000539 | D16: 69040 | E16: นาง มะลิวรรณ อยู่เจริญ | I16: 27000 | P16: 27000 | Q16: =SUM(F16+G16+H16+I16+J16+K16+L16+M16+N16+O16-P16) -> 0 | R16: PoonBKK
A17: 13 | B17: 44656 | C17: STHBKK012204000541 | D17: 54317 | E17: นาง ขวัญจิตร์ กลิ่นเจริญ | I17: 5000 | P17: 5000 | Q17: =SUM(F17+G17+H17+I17+J17+K17+L17+M17+N17+O17-P17) -> 0 | R17: lFrAmEl
A18: 14 | B18: 44656 | C18: STHBKK012204000543 | D18: 54503 | E18: นาย สมศักดิ์ พิมพ์หนู | J18: 10000 | P18: 10000 | Q18: =SUM(F18+G18+H18+I18+J18+K18+L18+M18+N18+O18-P18) -> 0 | R18: PoonBKK
A19: 15 | B19: 44656 | C19: STHBKK012204000544 | D19: 51051 | E19: นาย พรชัย คูสกุล | I19: 19900 | P19: 19900 | Q19: =SUM(F19+G19+H19+I19+J19+K19+L19+M19+N19+O19-P19) -> 0 | R19: Katae BKK
A20: 16 | B20: 44656 | C20: STHBKK012204000545 | D20: 45096 | E20: นาย วิเชษฐ สกุลหอม | I20: 3125 | P20: 3125 | Q20: =SUM(F20+G20+H20+I20+J20+K20+L20+M20+N20+O20-P20) -> 0 | R20: lFrAmEl
A21: 17 | B21: 44656 | C21: STHBKK012204000546 | D21: 57499 | E21: นาย ทนงศักดิ์ รัตนบุรี | J21: 5200 | P21: 5200 | Q21: =SUM(F21+G21+H21+I21+J21+K21+L21+M21+N21+O21-P21) -> 0 | R21: Katae BKK
A22: 18 | B22: 44656 | C22: STHBKK012204000547 | D22: 54515 | E22: นาย รุ่งมงคล พวงจำปา | J22: 2700 | P22: 2700 | Q22: =SUM(F22+G22+H22+I22+J22+K22+L22+M22+N22+O22-P22) -> 0 | R22: PoonBKK
A23: 19 | B23: 44656 | C23: STHBKK012204000548 | D23: 63098 | E23: นาง สุชานาถ ทะยานรัมย์ | J23: 5000 | P23: 5000 | Q23: =SUM(F23+G23+H23+I23+J23+K23+L23+M23+N23+O23-P23) -> 0 | R23: PoonBKK
A24: 20 | B24: 44656 | C24: STHBKK012204000549 | D24: 59904 | E24: นาย สุรทัศน์ เกไธสร | I24: 700 | P24: 700 | Q24: =SUM(F24+G24+H24+I24+J24+K24+L24+M24+N24+O24-P24) -> 0 | R24: PoonBKK
A25: 21 | B25: 44656 | C25: STHBKK012204000550 | D25: 53160 | E25: นาย วินัย ธงชัย | J25: 6250 | P25: 6250 | Q25: =SUM(F25+G25+H25+I25+J25+K25+L25+M25+N25+O25-P25) -> 0 | R25: PoonBKK
A26: 22 | B26: 44656 | C26: STHBKK012204000552 | D26: 53160 | E26: นาย วินัย ธงชัย | J26: 5000 | P26: 5000 | Q26: =SUM(F26+G26+H26+I26+J26+K26+L26+M26+N26+O26-P26) -> 0 | R26: PoonBKK
A27: 23 | B27: 44656 | C27: STHBKK012204000554 | D27: 48631 | E27: ดร. โนรี เต๊ะหละ | I27: 15000 | P27: 15000 | Q27: =SUM(F27+G27+H27+I27+J27+K27+L27+M27+N27+O27-P27) -> 0 | R27: lFrAmEl
A28: 24 | B28: 44656 | C28: STHBKK012204000555 | D28: 63406 | E28: นาย วุฒิชัย มุระดา | I28: 3350 | P28: 3350 | Q28: =SUM(F28+G28+H28+I28+J28+K28+L28+M28+N28+O28-P28) -> 0 | R28: lFrAmEl
A29: 25 | B29: 44656 | C29: STHBKK012204000556 | D29: 67137 | E29: นางสาว กนกพร ผิวเขียว | I29: 27000 | P29: 27000 | Q29: =SUM(F29+G29+H29+I29+J29+K29+L29+M29+N29+O29-P29) -> 0 | R29: Katae BKK
A30: 26 | B30: 44656 | C30: STHBKK012204000557 | D30: 51876 | E30: นางสาว จิราภรณ์ เขาทอง | I30: 40200 | P30: 40200 | Q30: =SUM(F30+G30+H30+I30+J30+K30+L30+M30+N30+O30-P30) -> 0 | R30: lFrAmEl
A31: 27 | B31: 44656 | C31: STHBKK012204000561 | D31: 52973 | E31: นาย สมรวม กุลโสภณ | I31: 3600 | P31: 3600 | Q31: =SUM(F31+G31+H31+I31+J31+K31+L31+M31+N31+O31-P31) -> 0 | R31: bkk-nee
A32: 28 | B32: 44656 | C32: STHBKK012204000562 | D32: 50436 | E32: นาง พิชาวีร์ บวรธีราเศรษฐ์ | I32: 10600 | P32: 10600 | Q32: =SUM(F32+G32+H32+I32+J32+K32+L32+M32+N32+O32-P32) -> 0 | R32: bkk-nee
A33: 29 | B33: 44656 | C33: STHBKK012204000564 | D33: 51406 | E33: บริษัท สวนสุข จำกัด(สำนักงานใหญ่) | I33: 8300 | P33: 8300 | Q33: =SUM(F33+G33+H33+I33+J33+K33+L33+M33+N33+O33-P33) -> 0 | R33: lFrAmEl
A34: 30 | B34: 44656 | C34: STHBKK012204000565 | D34: 52681 | E34: นาย ธนธรณ์ ปัจฉิมพาณิชย์ | I34: 1400 | P34: 1400 | Q34: =SUM(F34+G34+H34+I34+J34+K34+L34+M34+N34+O34-P34) -> 0 | R34: PoonBKK
A35: 31 | B35: 44656 | C35: STHBKK012204000569 | D35: 36769 | E35: นาย ยศพัทธิ์ ศรีอุทิศ | I35: 25000 | P35: 25000 | Q35: =SUM(F35+G35+H35+I35+J35+K35+L35+M35+N35+O35-P35) -> 0 | R35: lFrAmEl
A36: 32 | B36: 44656 | C36: STHBKK012204000570 | D36: 45193 | E36: นาง ศิลา สงอาจินต์ | I36: 59500 | P36: 59500 | Q36: =SUM(F36+G36+H36+I36+J36+K36+L36+M36+N36+O36-P36) -> 0 | R36: Katae BKK
A37: 33 | B37: 44656 | C37: STHBKK012204000573 | D37: 13781 | E37: นาย สุรวัฒน์ ตั้งพงศ์ศิรประภา | I37: 15000 | P37: 15000 | Q37: =SUM(F37+G37+H37+I37+J37+K37+L37+M37+N37+O37-P37) -> 0 | R37: Katae BKK
A38: 34 | B38: 44656 | C38: STHBKK012204000574 | D38: 14329 | E38: นาย มงคล เพ็งเคียน | I38: 700 | P38: 700 | Q38: =SUM(F38+G38+H38+I38+J38+K38+L38+M38+N38+O38-P38) -> 0 | R38: bkk-nee
... A42: 38 | B42: 44656 | C42: STHBKK012204000579 | D42: 51051 | E42: นาย พรชัย คูสกุล | I42: 15000 | P42: 15000 | Q42: =SUM(F42+G42+H42+I42+J42+K42+L42+M42+N42+O42-P42) -> 0 | R42: bkk-nee
A43: 39 | B43: 44656 | C43: STHBKK012204000580 | D43: 48482 | E43: นาง นาง สิริรัตน์ อินทร์ศักดิ์ | J43: 3700 | P43: 3700 | Q43: =SUM(F43+G43+H43+I43+J43+K43+L43+M43+N43+O43-P43) -> 0 | R43: PoonBKK
...

Sheet 07.04.65
A1: DAILY SALE 07 APRIL 2022
A2: NO | B2: วันที่ | C2: เลขออเดอร์ | D2: รหัส | E2: Name | F2: Payment | R2: CS ผู้คีย์บิล
F3: Cash | G3: Credit Card | I3: Tranfer Money | K3: E-WALLET | L3: Paypal | M3: qr paymet | N3: หักคอม | O3: ARP | P3: ยอดในระบบ | Q3: ผลต่าง
G4: Front Office | H4: Online | I4: KBANK | J4: KTB
A5: 1 | B5: 44656 | C5: STHBKK012204000653 | D5: 10320 | E5: บริษัท รีโวเด็ค จำกัด (สำนักงานใหญ่) | I5: 0 | P5: 1250 | Q5: =SUM(F5+G5+H5+I5+J5+K5+L5+M5+N5+O5-P5) -> -1250 | R5: Katae BKK
A6: 2 | B6: 44658 | C6: STHBKK012204000654 | D6: 51939 | E6: บริษัท รินทร์รฐา กรุ๊ป จำกัด(สำนักงานใหญ่) | I6: 11400 | P6: 11400 | Q6: =SUM(F6+G6+H6+I6+J6+K6+L6+M6+N6+O6-P6) -> 0 | R6: PoonBKK
A7: 3 | B7: 44658 | C7: STHBKK012204000656 | D7: 53249 | E7: ห้างหุ้นส่วนจำกัด ปูแดงพารวย ( สำนักงานใหญ่) | I7: 16250 | P7: 16250 | Q7: =SUM(F7+G7+H7+I7+J7+K7+L7+M7+N7+O7-P7) -> 0 | R7: bkk-aoeng
A8: 4 | B8: 44658 | C8: STHBKK012204000657 | D8: 50474 | E8: นาย ณัฐพล ศรีทอง | I8: 25000 | P8: 25000 | Q8: =SUM(F8+G8+H8+I8+J8+K8+L8+M8+N8+O8-P8) -> 0 | R8: PoonBKK
A9: 5 | B9: 44658 | C9: STHBKK012204000658 | D9: 69213 | E9: นาย พิสิษฐ์ ดาบเงิน | I9: 27000 | P9: 27000 | Q9: =SUM(F9+G9+H9+I9+J9+K9+L9+M9+N9+O9-P9) -> 0 | R9: Katae BKK
A10: 6 | B10: 44658 | C10: STHBKK012204000663 | D10: 48136 | E10: พ.ต.ท. วิรุฬ อินทร์มีสุข | I10: 2850 | P10: 2850 | Q10: =SUM(F10+G10+H10+I10+J10+K10+L10+M10+N10+O10-P10) -> 0 | R10: PoonBKK
A11: 7 | B11: 44658 | C11: STHBKK012204000664 | D11: 59452 | E11: นาย บุญลักษณ์ แสงอุ่น | I11: 25000 | P11: 25000 | Q11: =SUM(F11+G11+H11+I11+J11+K11+L11+M11+N11+O11-P11) -> 0 | R11: Katae BKK
A12: 8 | B12: 44658 | C12: STHBKK012204000665 | D12: 53663 | E12: นาย พงศ์อมร เด่นดวง | I12: 25580 | P12: 25580 | Q12: =SUM(F12+G12+H12+I12+J12+K12+L12+M12+N12+O12-P12) -> 0 | R12: bkk-aoeng
A13: 9 | B13: 44658 | C13: STHBKK012204000666 | D13: 58119 | E13: นางสาว เบญจพร ชุมรักษา | I13: 2650 | P13: 2650 | Q13: =SUM(F13+G13+H13+I13+J13+K13+L13+M13+N13+O13-P13) -> 0 | R13: bkk-aoeng
A14: 10 | B14: 44658 | C14: STHBKK012204000667 | D14: 53249 | E14: ห้างหุ้นส่วนจำกัด ปูแดงพารวย ( สำนักงานใหญ่) | F14: 200 | P14: 200 | Q14: =SUM(F14+G14+H14+I14+J14+K14+L14+M14+N14+O14-P14) -> 0 | R14: bkk-aoeng
A15: 11 | B15: 44658 | C15: STHBKK012204000669 | D15: 59990 | E15: นาย นภวิถี พานิชประไพ | I15: 1450 | P15: 1450 | Q15: =SUM(F15+G15+H15+I15+J15+K15+L15+M15+N15+O15-P15) -> 0 | R15: bkk-aoeng
A16: 12 | B16: 44658 | C16: STHBKK012204000670 | D16: 69214 | E16: นาย SOUKCHALEUN BOUNYASITH | I16: 27000 | P16: 27000 | Q16: =SUM(F16+G16+H16+I16+J16+K16+L16+M16+N16+O16-P16) -> 0 | R16: PoonBKK
A17: 13 | B17: 44658 | C17: STHBKK012204000671 | D17: 45937 | E17: นาย วัชรชัย ขุนศรีรักษา | I17: 25000 | P17: 25000 | Q17: =SUM(F17+G17+H17+I17+J17+K17+L17+M17+N17+O17-P17) -> 0 | R17: PoonBKK
A18: 14 | B18: 44658 | C18: STHBKK012204000673 | D18: 62809 | E18: นางสาว วรารัตน์ ฤกษ์ศรี | I18: 5200 | P18: 5200 | Q18: =SUM(F18+G18+H18+I18+J18+K18+L18+M18+N18+O18-P18) -> 0 | R18: bkk-aoeng
A19: 15 | B19: 44658 | C19: STHBKK012204000674 | D19: 41915 | E19: นาย บุญเกิด พลรัตน์ | I19: 3750 | P19: 3750 | Q19: =SUM(F19+G19+H19+I19+J19+K19+L19+M19+N19+O19-P19) -> 0 | R19: PoonBKK
A20: 16 | B20: 44658 | C20: STHBKK012204000675 | D20: 53495 | E20: นางสาว ธนัญชนก อยู่ยงค์ | I20: 10000 | P20: 10000 | Q20: =SUM(F20+G20+H20+I20+J20+K20+L20+M20+N20+O20-P20) -> 0 | R20: PoonBKK
A21: 17 | B21: 44658 | C21: STHBKK012204000677 | D21: 69217 | E21: นาย สุรพล สงวนสิทธิ์ | I21: 300 | P21: 300 | Q21: =SUM(F21+G21+H21+I21+J21+K21+L21+M21+N21+O21-P21) -> 0 | R21: Katae BKK
A22: 18 | B22: 44658 | C22: STHBKK012204000678 | D22: 69217 | E22: นาย สุรพล สงวนสิทธิ์ | I22: 500 | P22: 500 | Q22: =SUM(F22+G22+H22+I22+J22+K22+L22+M22+N22+O22-P22) -> 0 | R22: Katae BKK
A23: 19 | B23: 44658 | C23: STHBKK012204000679 | D23: 67687 | E23: นางสาว วธิดา ไตรรัตน์ | I23: 625 | P23: 625 | Q23: =SUM(F23+G23+H23+I23+J23+K23+L23+M23+N23+O23-P23) -> 0 | R23: Katae BKK
A24: 20 | B24: 44658 | C24: STHBKK012204000680 | D24: 22332 | E24: นางสาว คณาง ไพรบึง | I24: 5150 | P24: 5150 | Q24: =SUM(F24+G24+H24+I24+J24+K24+L24+M24+N24+O24-P24) -> 0 | R24: Katae BKK
A25: 21 | B25: 44658 | C25: STHBKK012204000681 | D25: 51976 | E25: นาง วรัทยา จันทร์ชื่น | J25: 16250 | P25: 16250 | Q25: =SUM(F25+G25+H25+I25+J25+K25+L25+M25+N25+O25-P25) -> 0 | R25: bkk-aoeng
A26: 22 | B26: 44658 | C26: STHBKK012204000685 | D26: 61479 | E26: นางสาว วรวิมล ภูชฎาภิรมย์ | I26: 1250 | P26: 1250 | Q26: =SUM(F26+G26+H26+I26+J26+K26+L26+M26+N26+O26-P26) -> 0 | R26: Katae BKK
A27: 23 | B27: 44658 | C27: STHBKK012204000686 | D27: 61479 | E27: นางสาว วรวิมล ภูชฎาภิรมย์ | I27: 1000 | P27: 1000 | Q27: =SUM(F27+G27+H27+I27+J27+K27+L27+M27+N27+O27-P27) -> 0 | R27: Katae BKK
A28: 24 | B28: 44658 | C28: STHBKK012204000688 | D28: 48052 | E28: นาง นภาไพลิน กาละวันต์ | I28: 1400 | P28: 1400 | Q28: =SUM(F28+G28+H28+I28+J28+K28+L28+M28+N28+O28-P28) -> 0 | R28: PoonBKK
A29: 25 | B29: 44658 | C29: STHBKK012204000689 | D29: 45096 | E29: นาย วิเชษฐ สกุลหอม | I29: 5150 | P29: 5150 | Q29: =SUM(F29+G29+H29+I29+J29+K29+L29+M29+N29+O29-P29) -> 0 | R29: bkk-aoeng
A30: 26 | B30: 44658 | C30: STHBKK012204000691 | D30: 68041 | E30: นาย สมเกียรติ ครุฑจันทร์ | I30: 2650 | P30: 2650 | Q30: =SUM(F30+G30+H30+I30+J30+K30+L30+M30+N30+O30-P30) -> 0 | R30: Katae BKK
A31: 27 | B31: 44658 | C31: STHBKK012204000692 | D31: 21818 | E31: ห้างหุ้นส่วนจำกัด ไดม่อนอันดามัน เน็ตเวิร์ค (สำนักงานใหญ่) | I31: 1600 | P31: 1600 | Q31: =SUM(F31+G31+H31+I31+J31+K31+L31+M31+N31+O31-P31) -> 0 | R31: Katae BKK
A32: 28 | B32: 44658 | C32: STHBKK012204000693 | D32: 39286 | E32: นาย สุวิทย์ มั่นเขตวิทย์ | I32: 5000 | P32: 5000 | Q32: =SUM(F32+G32+H32+I32+J32+K32+L32+M32+N32+O32-P32) -> 0 | R32: Katae BKK
A33: 29 | B33: 44658 | C33: STHBKK012204000694 | D33: 39286 | E33: นาย สุวิทย์ มั่นเขตวิทย์ | I33: 1400 | P33: 1400 | Q33: =SUM(F33+G33+H33+I33+J33+K33+L33+M33+N33+O33-P33) -> 0 | R33: Katae BKK
A34: 30 | B34: 44658 | C34: STHBKK012204000695 | D34: 36769 | E34: นาย ยศพัทธิ์ ศรีอุทิศ | I34: 19200 | P34: 19200 | Q34: =SUM(F34+G34+H34+I34+J34+K34+L34+M34+N34+O34-P34) -> 0 | R34: PoonBKK
A35: 31 | B35: 44658 | C35: STHBKK012204000696 | D35: 53089 | E35: นาง ทิพวัลย์ วงษ์ธัญกรณ์ | I35: 5000 | P35: 5000 | Q35: =SUM(F35+G35+H35+I35+J35+K35+L35+M35+N35+O35-P35) -> 0 | R35: PoonBKK
A36: 32 | B36: 44658 | C36: STHBKK012204000697 | D36: 53043 | E36: นาง ทัศนีย์ ทองถาวรวงศ์ | I36: 5000 | P36: 5000 | Q36: =SUM(F36+G36+H36+I36+J36+K36+L36+M36+N36+O36-P36) -> 0 | R36: PoonBKK
A37: 33 | B37: 44658 | C37: STHBKK012204000698 | D37: 64740 | E37: นางสาว มนัสนันท์ อ่อนศิริ | J37: 2650 | P37: 2650 | Q37: =SUM(F37+G37+H37+I37+J37+K37+L37+M37+N37+O37-P37) -> 0 | R37: bkk-aoeng
A38: 34 | B38: 44658 | C38: STHBKK012204000699 | D38: 10320 | E38: บริษัท รีโวเด็ค จำกัด (สำนักงานใหญ่) | I38: 3500 | P38: 3500 | Q38: =SUM(F38+G38+H38+I38+J38+K38+L38+M38+N38+O38-P38) -> 0 | R38: Katae BKK
A39: 35 | B39: 44658 | C39: STHBKK012204000700 | D39: 48631 | E39: ดร. โนรี เต๊ะหละ | I39: 2100 | P39: 2100 | Q39: =SUM(F39+G39+H39+I39+J39+K39+L39+M39+N39+O39-P39) -> 0 | R39: bkk-aoeng
A40: 36 | B40: 44658 | C40: STHBKK012204000701 | D40: 52647 | E40: นางสาว เยาวดี สำเภา | I40: 2500 | P40: 2500 | Q40: =SUM(F40+G40+H40+I40+J40+K40+L40+M40+N40+O40-P40) -> 0 | R40: bkk-aoeng
...

Sheet 8.04.65
A1: DAILY SALE 8 APRIL 2022
A2: NO | B2: วันที่ | C2: เลขออเดอร์ | D2: รหัส | E2: Name | F2: Payment | R2: CS ผู้คีย์บิล
F3: Cash | G3: Credit Card | I3: Tranfer Money | K3: E-WALLET | L3: Paypal | M3: qr paymet | N3: หักคอม | O3: ARP | P3: ยอดในระบบ | Q3: ผลต่าง
G4: Front Office | H4: Online | I4: KBANK | J4: KTB
A5: 1 | B5: 44658 | C5: STHBKK012204000855 | D5: 17778 | E5: นางสาว ชนัญกันย์ แพร่พิพัฒน์ | G5: 5000 | P5: 5000 | Q5: =SUM(F5+G5+H5+I5+J5+K5+L5+M5+N5+O5-P5) -> 0 | R5: PoonBKK
A6: 2 | B6: 44658 | C6: STHBKK012204000856 | D6: 17778 | E6: นางสาว ชนัญกันย์ แพร่พิพัฒน์ | F6: 1450 | P6: 1450 | Q6: =SUM(F6+G6+H6+I6+J6+K6+L6+M6+N6+O6-P6) -> 0 | R6: PoonBKK
A7: 3 | B7: 44658 | C7: STHBKK012204000857 | D7: 20541 | E7: นาย พุฒิพัฒน์ รัตนพิริยสกุล | F7: 400 | P7: 400 | Q7: =SUM(F7+G7+H7+I7+J7+K7+L7+M7+N7+O7-P7) -> 0 | R7: PoonBKK
A8: 4 | B8: 44658 | C8: STHBKK012204000858 | D8: 52083 | E8: บริษัท ศรีทวีรุ่งโรจน์ จำกัด(สำนักงานใหญ่) | I8: 0 | P8: 65500 | Q8: =SUM(F8+G8+H8+I8+J8+K8+L8+M8+N8+O8-P8) -> -65500 | R8: Katae BKK
A9: 5 | B9: 44658 | C9: STHBKK012204000859 | D9: 20541 | E9: นาย พุฒิพัฒน์ รัตนพิริยสกุล | F9: 150 | P9: 150 | Q9: =SUM(F9+G9+H9+I9+J9+K9+L9+M9+N9+O9-P9) -> 0 | R9: Katae BKK
A10: 6 | B10: 44658 | C10: STHBKK012204000860 | D10: 51512 | E10: นาย ดิลก แผ่ทอง | J10: 9800 | P10: 9800 | Q10: =SUM(F10+G10+H10+I10+J10+K10+L10+M10+N10+O10-P10) -> 0 | R10: bkk-aoeng
A11: 7 | B11: 44658 | C11: STHBKK012204000862 | D11: 48631 | E11: ดร. โนรี เต๊ะหละ | I11: 15000 | P11: 15000 | Q11: =SUM(F11+G11+H11+I11+J11+K11+L11+M11+N11+O11-P11) -> 0 | R11: lFrAmEl
A12: 8 | B12: 44658 | C12: STHBKK012204000863 | D12: 48053 | E12: นาย ต้นสัก สุคนธรัตน์ | I12: 2700 | P12: 2700 | Q12: =SUM(F12+G12+H12+I12+J12+K12+L12+M12+N12+O12-P12) -> 0 | R12: lFrAmEl
A13: 9 | B13: 44659 | C13: STHBKK012204000866 | D13: 53249 | E13: ห้างหุ้นส่วนจำกัด ปูแดงพารวย ( สำนักงานใหญ่) | I13: 7500 | P13: 7500 | Q13: =SUM(F13+G13+H13+I13+J13+K13+L13+M13+N13+O13-P13) -> 0 | R13: bkk-aoeng
A14: 10 | B14: 44659 | C14: STHBKK012204000867 | D14: 53249 | E14: ห้างหุ้นส่วนจำกัด ปูแดงพารวย ( สำนักงานใหญ่) | F14: 200 | P14: 200 | Q14: =SUM(F14+G14+H14+I14+J14+K14+L14+M14+N14+O14-P14) -> 0 | R14: bkk-aoeng
A15: 11 | B15: 44659 | C15: STHBKK012204000868 | D15: 69190 | E15: นางสาว ลัดดาวรรณ์ จันทร์นวล | I15: 300 | P15: 300 | Q15: =SUM(F15+G15+H15+I15+J15+K15+L15+M15+N15+O15-P15) -> 0 | R15: PoonBKK
A16: 12 | B16: 44659 | C16: STHBKK012204000869 | D16: 69193 | E16: นางสาว พิมพ์ลภัส ยงหนู | I16: 300 | P16: 300 | Q16: =SUM(F16+G16+H16+I16+J16+K16+L16+M16+N16+O16-P16) -> 0 | R16: PoonBKK
A17: 13 | B17: 44659 | C17: STHBKK012204000871 | D17: 46927 | E17: นาย พิสิฐพงษ์ ยอดจันทร์ | I17: 6400 | P17: 6400 | Q17: =SUM(F17+G17+H17+I17+J17+K17+L17+M17+N17+O17-P17) -> 0 | R17: BKK-Neng
A18: 14 | B18: 44659 | C18: STHBKK012204000873 | D18: 46927 | E18: นาย พิสิฐพงษ์ ยอดจันทร์ | I18: 400 | P18: 400 | Q18: =SUM(F18+G18+H18+I18+J18+K18+L18+M18+N18+O18-P18) -> 0 | R18: BKK-Neng
A19: 15 | B19: 44659 | C19: STHBKK012204000874 | D19: 35227 | E19: นาย พีรพงศ์ ภรประเสริฐศรี | G19: 10000 | P19: 10000 | Q19: =SUM(F19+G19+H19+I19+J19+K19+L19+M19+N19+O19-P19) -> 0 | R19: PoonBKK
A20: 16 | B20: 44659 | C20: STHBKK012204000876 | D20: 49677 | E20: นาย ชาลี ดีฤสานต์ | J20: 15000 | P20: 15000 | Q20: =SUM(F20+G20+H20+I20+J20+K20+L20+M20+N20+O20-P20) -> 0 | R20: PoonBKK
A21: 17 | B21: 44659 | C21: STHBKK012204000877 | D21: 61479 | E21: นางสาว วรวิมล ภูชฎาภิรมย์ | I21: 1050 | P21: 1050 | Q21: =SUM(F21+G21+H21+I21+J21+K21+L21+M21+N21+O21-P21) -> 0 | R21: PoonBKK
A22: 18 | B22: 44659 | C22: STHBKK012204000878 | D22: 13781 | E22: นาย สุรวัฒน์ ตั้งพงศ์ศิรประภา | I22: 15000 | P22: 15000 | Q22: =SUM(F22+G22+H22+I22+J22+K22+L22+M22+N22+O22-P22) -> 0 | R22: PoonBKK
A23: 19 | B23: 44659 | C23: STHBKK012204000879 | D23: 13781 | E23: นาย สุรวัฒน์ ตั้งพงศ์ศิรประภา | I23: 10000 | P23: 10000 | Q23: =SUM(F23+G23+H23+I23+J23+K23+L23+M23+N23+O23-P23) -> 0 | R23: PoonBKK
A24: 20 | B24: 44659 | C24: STHBKK012204000880 | D24: 10320 | E24: บริษัท รีโวเด็ค จำกัด (สำนักงานใหญ่) | I24: 10000 | P24: 10000 | Q24: =SUM(F24+G24+H24+I24+J24+K24+L24+M24+N24+O24-P24) -> 0 | R24: PoonBKK
A25: 21 | B25: 44659 | C25: STHBKK012204000882 | D25: 69247 | E25: นางสาว ณัฐรดา รัตนากรรติกุล | I25: 27000 | P25: 27000 | Q25: =SUM(F25+G25+H25+I25+J25+K25+L25+M25+N25+O25-P25) -> 0 | R25: bkk-aoeng
A26: 22 | B26: 44659 | C26: STHBKK012204000883 | D26: 66961 | E26: นาย ถนอม ยาตรา | I26: 500 | P26: 500 | Q26: =SUM(F26+G26+H26+I26+J26+K26+L26+M26+N26+O26-P26) -> 0 | R26: PoonBKK
A27: 23 | B27: 44659 | C27: STHBKK012204000884 | D27: 21821 | E27: ห้างหุ้นส่วนจำกัด เครือข่ายปิยธนา ( สำนักงานใหญ่ ) | I27: 4500 | P27: 4500 | Q27: =SUM(F27+G27+H27+I27+J27+K27+L27+M27+N27+O27-P27) -> 0 | R27: PoonBKK
A28: 24 | B28: 44659 | C28: STHBKK012204000886 | D28: 24751 | E28: นาย ณัฐพนธ์ แพร่พิพัฒน์ | I28: 450 | P28: 450 | Q28: =SUM(F28+G28+H28+I28+J28+K28+L28+M28+N28+O28-P28) -> 0 | R28: bkk-aoeng
A29: 25 | B29: 44659 | C29: STHBKK012204000888 | D29: 22280 | E29: นาย พีระพงศ์ สิงหพล | I29: 5990 | P29: 5990 | Q29: =SUM(F29+G29+H29+I29+J29+K29+L29+M29+N29+O29-P29) -> 0 | R29: bkk-aoeng
A30: 26 | B30: 44659 | C30: STHBKK012204000891 | D30: 69250 | E30: นางสาว ณวรัณ เจียมเงิน | I30: 27000 | P30: 27000 | Q30: =SUM(F30+G30+H30+I30+J30+K30+L30+M30+N30+O30-P30) -> 0 | R30: PoonBKK
A31: 27 | B31: 44659 | C31: STHBKK012204000893 | D31: 54559 | E31: นางสาว รสริน ขอเอื้อนกลาง | I31: 15000 | P31: 15000 | Q31: =SUM(F31+G31+H31+I31+J31+K31+L31+M31+N31+O31-P31) -> 0 | R31: bkk-aoeng
A32: 28 | B32: 44659 | C32: STHBKK012204000898 | D32: 47179 | E32: บริษัท ต้องรวย จำกัด ( สำนักงานใหญ่ ) | I32: 1050 | P32: 1050 | Q32: =SUM(F32+G32+H32+I32+J32+K32+L32+M32+N32+O32-P32) -> 0 | R32: PoonBKK
A33: 29 | B33: 44659 | C33: STHBKK012204000899 | D33: 50222 | E33: บริษัท หลานหยิน จำกัด ( สำนักงานใหญ่ ) | I33: 700 | P33: 700 | Q33: =SUM(F33+G33+H33+I33+J33+K33+L33+M33+N33+O33-P33) -> 0 | R33: PoonBKK
A34: 30 | B34: 44659 | C34: STHBKK012204000900 | D34: 26040 | E34: นางสาว เพลิน รายสันเทียะ | J34: 5000 | P34: 5000 | Q34: =SUM(F34+G34+H34+I34+J34+K34+L34+M34+N34+O34-P34) -> 0 | R34: PoonBKK
A35: 31 | B35: 44659 | C35: STHBKK012204000901 | D35: 26040 | E35: นางสาว เพลิน รายสันเทียะ | J35: 5000 | P35: 5000 | Q35: =SUM(F35+G35+H35+I35+J35+K35+L35+M35+N35+O35-P35) -> 0 | R35: PoonBKK
A36: 32 | B36: 44659 | C36: STHBKK012204000904 | D36: 27066 | E36: นาย ชลธี จันทโคตร | I36: 10600 | P36: 10600 | Q36: =SUM(F36+G36+H36+I36+J36+K36+L36+M36+N36+O36-P36) -> 0 | R36: PoonBKK
A37: 33 | B37: 44659 | C37: STHBKK012204000905 | D37: 46778 | E37: นาย ปรีชา แก้วโกถม | J37: 9300 | P37: 9300 | Q37: =SUM(F37+G37+H37+I37+J37+K37+L37+M37+N37+O37-P37) -> 0 | R37: PoonBKK
A38: 34 | B38: 44659 | C38: STHBKK012204000907 | D38: 60282 | E38: นาง ณฐมน เสมือนคิด | J38: 1250 | P38: 1250 | Q38: =SUM(F38+G38+H38+I38+J38+K38+L38+M38+N38+O38-P38) -> 0 | R38: bkk-aoeng
A39: 35 | B39: 44659 | C39: STHBKK012204000908 | D39: 57499 | E39: นาย ทนงศักดิ์ รัตนบุรี | I39: 5000 | P39: 5000 | Q39: =SUM(F39+G39+H39+I39+J39+K39+L39+M39+N39+O39-P39) -> 0 | R39: BKK-Neng
A40: 36 | B40: 44659 | C40: STHBKK012204000909 | D40: 48052 | E40: นาง นภาไพลิน กาละวันต์ | I40: 2700 | P40: 2700 | Q40: =SUM(F40+G40+H40+I40+J40+K40+L40+M40+N40+O40-P40) -> 0 | R40: bkk-aoeng
...

Sheet 9.04.65
A1: DAILY SALE 9 APRIL 2022
A2: NO | B2: วันที่ | C2: เลขออเดอร์ | D2: รหัส | E2: Name | F2: Payment | R2: CS ผู้คีย์บิล
F3: Cash | G3: Credit Card | I3: Tranfer Money | K3: E-WALLET | L3: Paypal | M3: qr paymet | N3: หักคอม | O3: ARP | P3: ยอดในระบบ | Q3: ผลต่าง
G4: Front Office | H4: Online | I4: KBANK | J4: KTB
A5: 1 | B5: 44659 | C5: STHBKK012204001008 | D5: 25650 | E5: นาง ศศกร อมตวงษ์ | K5: 0 | P5: 2500 | Q5: =SUM(F5+G5+H5+I5+J5+K5+L5+M5+N5+O5-P5) -> -2500 | R5: PoonBKK
A6: 2 | B6: 44659 | C6: STHBKK012204001009 | D6: 51939 | E6: บริษัท รินทร์รฐา กรุ๊ป จำกัด(สำนักงานใหญ่) | I6: 0 | P6: 11950 | Q6: =SUM(F6+G6+H6+I6+J6+K6+L6+M6+N6+O6-P6) -> -11950 | R6: bkk-aoeng
A7: 3 | B7: 44660 | C7: STHBKK012204001010 | D7: 53249 | E7: ห้างหุ้นส่วนจำกัด ปูแดงพารวย ( สำนักงานใหญ่) | J7: 15000 | P7: 15000 | Q7: =SUM(F7+G7+H7+I7+J7+K7+L7+M7+N7+O7-P7) -> 0 | R7: Katae BKK
A8: 4 | B8: 44660 | C8: STHBKK012204001011 | D8: 22727 | E8: นิรันดร์ สันอีด | I8: 500 | P8: 500 | Q8: =SUM(F8+G8+H8+I8+J8+K8+L8+M8+N8+O8-P8) -> 0 | R8: Katae BKK
A9: 5 | B9: 44660 | C9: STHBKK012204001012 | D9: 64405 | E9: นาย ยรรยงค์ มุกดา | I9: 2650 | P9: 2650 | Q9: =SUM(F9+G9+H9+I9+J9+K9+L9+M9+N9+O9-P9) -> 0 | R9: Katae BKK
A10: 6 | B10: 44660 | C10: STHBKK012204001016 | D10: 69270 | E10: นางสาว ศรีวรรณ์ ศรศิลป์ | J10: 300 | P10: 300 | Q10: =SUM(F10+G10+H10+I10+J10+K10+L10+M10+N10+O10-P10) -> 0 | R10: bkk-aoeng
A11: 7 | B11: 44660 | C11: STHBKK012204001017 | D11: 69271 | E11: นาย นิรันดร์ พัฒนศิริ | J11: 27000 | P11: 27000 | Q11: =SUM(F11+G11+H11+I11+J11+K11+L11+M11+N11+O11-P11) -> 0 | R11: bkk-aoeng
A12: 8 | B12: 44660 | C12: STHBKK012204001023 | D12: 45227 | E12: นางสาว ประภัสสร ดีดวงพันธ์ | I12: 2500 | P12: 2500 | Q12: =SUM(F12+G12+H12+I12+J12+K12+L12+M12+N12+O12-P12) -> 0 | R12: Katae BKK
A13: 9 | B13: 44660 | C13: STHBKK012204001024 | D13: 62809 | E13: นางสาว วรารัตน์ ฤกษ์ศรี | I13: 5000 | P13: 5000 | Q13: =SUM(F13+G13+H13+I13+J13+K13+L13+M13+N13+O13-P13) -> 0 | R13: BKK-Neng
A14: 10 | B14: 44660 | C14: STHBKK012204001025 | D14: 10250 | E14: นาย สุรวิทย์ ทิพยโสภากุล | J14: 2500 | P14: 2500 | Q14: =SUM(F14+G14+H14+I14+J14+K14+L14+M14+N14+O14-P14) -> 0 | R14: Katae BKK
A15: 11 | B15: 44660 | C15: STHBKK012204001026 | D15: 51782 | E15: นาย สุวิทย์ รองชูเพ็ง | J15: 350 | P15: 350 | Q15: =SUM(F15+G15+H15+I15+J15+K15+L15+M15+N15+O15-P15) -> 0 | R15: Katae BKK
A16: 12 | B16: 44660 | C16: STHBKK012204001027 | D16: 44149 | E16: นางสาว วณัฐกมล วิไลลักษณ์ | I16: 26500 | P16: 26500 | Q16: =SUM(F16+G16+H16+I16+J16+K16+L16+M16+N16+O16-P16) -> 0 | R16: bkk-aoeng
A17: 13 | B17: 44660 | C17: STHBKK012204001028 | D17: 43134 | E17: นาย เพชร ภูมี | I17: 3600 | P17: 3600 | Q17: =SUM(F17+G17+H17+I17+J17+K17+L17+M17+N17+O17-P17) -> 0 | R17: bkk-aoeng
A18: 14 | B18: 44660 | C18: STHBKK012204001030 | D18: 10320 | E18: บริษัท รีโวเด็ค จำกัด (สำนักงานใหญ่) | I18: 20250 | P18: 20250 | Q18: =SUM(F18+G18+H18+I18+J18+K18+L18+M18+N18+O18-P18) -> 0 | R18: Katae BKK
A19: 15 | B19: 44660 | C19: STHBKK012204001031 | D19: 59904 | E19: นาย สุรทัศน์ เกไธสร | I19: 5000 | P19: 5000 | Q19: =SUM(F19+G19+H19+I19+J19+K19+L19+M19+N19+O19-P19) -> 0 | R19: bkk-aoeng
A20: 16 | B20: 44660 | C20: STHBKK012204001032 | D20: 55106 | E20: นาย สุวิทย์ โตทุ้ย | I20: 2650 | P20: 2650 | Q20: =SUM(F20+G20+H20+I20+J20+K20+L20+M20+N20+O20-P20) -> 0 | R20: Katae BKK
A21: 17 | B21: 44660 | C21: STHBKK012204001033 | D21: 53495 | E21: นางสาว ธนัญชนก อยู่ยงค์ | I21: 5000 | P21: 5000 | Q21: =SUM(F21+G21+H21+I21+J21+K21+L21+M21+N21+O21-P21) -> 0 | R21: bkk-aoeng
A22: 18 | B22: 44660 | C22: STHBKK012204001034 | D22: 53495 | E22: นางสาว ธนัญชนก อยู่ยงค์ | I22: 5000 | P22: 5000 | Q22: =SUM(F22+G22+H22+I22+J22+K22+L22+M22+N22+O22-P22) -> 0 | R22: bkk-aoeng
A23: 19 | B23: 44660 | C23: STHBKK012204001036 | D23: 56901 | E23: นาย ธำรงค์ศักดิ์ มะลิซ้อน | I23: 3900 | P23: 3900 | Q23: =SUM(F23+G23+H23+I23+J23+K23+L23+M23+N23+O23-P23) -> 0 | R23: Katae BKK
A24: 20 | B24: 44660 | C24: STHBKK012204001037 | D24: 27066 | E24: นาย ชลธี จันทโคตร | I24: 19900 | P24: 19900 | Q24: =SUM(F24+G24+H24+I24+J24+K24+L24+M24+N24+O24-P24) -> 0 | R24: bkk-aoeng
A25: 21 | B25: 44660 | C25: STHBKK012204001038 | D25: 67909 | E25: นางสาว สุธรรมา กุสันเทียะ | J25: 47500 | P25: 47500 | Q25: =SUM(F25+G25+H25+I25+J25+K25+L25+M25+N25+O25-P25) -> 0 | R25: Katae BKK
A26: 22 | B26: 44660 | C26: STHBKK012204001040 | D26: 58427 | E26: ห้างหุ้นส่วนจำกัด ลูกณัฐ มาร์เก็ตติ้ง (สำนักงานใหญ่) | I26: 5700 | P26: 5700 | Q26: =SUM(F26+G26+H26+I26+J26+K26+L26+M26+N26+O26-P26) -> 0 | R26: bkk-aoeng
A27: 23 | B27: 44660 | C27: STHBKK012204001041 | D27: 43380 | E27: นางสาว สุภาพร พรมทา | I27: 1050 | P27: 1050 | Q27: =SUM(F27+G27+H27+I27+J27+K27+L27+M27+N27+O27-P27) -> 0 | R27: Katae BKK
A28: 24 | B28: 44660 | C28: STHBKK012204001042 | D28: 58427 | E28: ห้างหุ้นส่วนจำกัด ลูกณัฐ มาร์เก็ตติ้ง (สำนักงานใหญ่) | F28: 7 | P28: 7 | Q28: =SUM(F28+G28+H28+I28+J28+K28+L28+M28+N28+O28-P28) -> 0 | R28: bkk-aoeng
A29: 25 | B29: 44660 | C29: STHBKK012204001043 | D29: 66774 | E29: นาย ศุภลักษณ์ สิมหะชาติ | J29: 350 | P29: 350 | Q29: =SUM(F29+G29+H29+I29+J29+K29+L29+M29+N29+O29-P29) -> 0 | R29: Katae BKK
A30: 26 | B30: 44660 | C30: STHBKK012204001044 | D30: 14329 | E30: นาย มงคล เพ็งเคียน | I30: 1250 | P30: 1250 | Q30: =SUM(F30+G30+H30+I30+J30+K30+L30+M30+N30+O30-P30) -> 0 | R30: bkk-aoeng
A31: 27 | B31: 44660 | C31: STHBKK012204001045 | D31: 50593 | E31: บริษัท วี.เอ็น.ซี.สกินแคร์ จำกัด ( สำนักงานใหญ่ ) | I31: 15000 | P31: 15000 | Q31: =SUM(F31+G31+H31+I31+J31+K31+L31+M31+N31+O31-P31) -> 0 | R31: Katae BKK
A32: 28 | B32: 44660 | C32: STHBKK012204001047 | D32: 27895 | E32: นาง สมจิตร นวนสุ่ม | J32: 5000 | P32: 5000 | Q32: =SUM(F32+G32+H32+I32+J32+K32+L32+M32+N32+O32-P32) -> 0 | R32: Katae BKK
A33: 29 | B33: 44660 | C33: STHBKK012204001048 | D33: 55158 | E33: นาย นิคม ยิ้มสาระ | J33: 5000 | P33: 5000 | Q33: =SUM(F33+G33+H33+I33+J33+K33+L33+M33+N33+O33-P33) -> 0 | R33: Katae BKK
A34: 30 | B34: 44660 | C34: STHBKK012204001049 | D34: 51939 | E34: บริษัท รินทร์รฐา กรุ๊ป จำกัด(สำนักงานใหญ่) | I34: 15900 | P34: 15900 | Q34: =SUM(F34+G34+H34+I34+J34+K34+L34+M34+N34+O34-P34) -> 0 | R34: bkk-aoeng
A35: 31 | B35: 44660 | C35: STHBKK012204001050 | D35: 10697 | E35: นางสาว พวงเพ็ญ สุวรรณโณ | I35: 2650 | P35: 2650 | Q35: =SUM(F35+G35+H35+I35+J35+K35+L35+M35+N35+O35-P35) -> 0 | R35: Katae BKK
A36: 32 | B36: 44660 | C36: STHBKK012204001051 | D36: 60421 | E36: นางสาว เกื้อกุล โชติช่วง | J36: 2500 | P36: 2500 | Q36: =SUM(F36+G36+H36+I36+J36+K36+L36+M36+N36+O36-P36) -> 0 | R36: BKK-Neng
A37: 33 | B37: 44660 | C37: STHBKK012204001052 | D37: 50595 | E37: บริษัท แก้วแกมทอง เทรดดิ้ง จำกัด (สำนักงานใหญ่) | I37: 73400 | P37: 73400 | Q37: =SUM(F37+G37+H37+I37+J37+K37+L37+M37+N37+O37-P37) -> 0 | R37: Katae BKK
A38: 34 | B38: 44660 | C38: STHBKK012204001053 | D38: 66838 | E38: นาย เสฎฐวุฒิ พนาอภิชน | I38: 8600 | P38: 8600 | Q38: =SUM(F38+G38+H38+I38+J38+K38+L38+M38+N38+O38-P38) -> 0 | R38: Katae BKK
A39: 35 | B39: 44660 | C39: STHBKK012204001054 | D39: 28414 | E39: นาง ณัฎฐณันธ์ วงวันดี | I39: 2850 | P39: 2850 | Q39: =SUM(F39+G39+H39+I39+J39+K39+L39+M39+N39+O39-P39) -> 0 | R39: Katae BKK
A40: 36 | B40: 44660 | C40: STHBKK012204001055 | D40: 35220 | E40: นาย ดัสนีย์​ เจะ​เลาะ​ | G40: 4450 | P40: 4450 | Q40: =SUM(F40+G40+H40+I40+J40+K40+L40+M40+N40+O40-P40) -> 0 | R40: Katae BKK
...

Sheet 10.04.65
A1: DAILY SALE 10 APRIL 2022
A2: NO | B2: วันที่ | C2: เลขออเดอร์ | D2: รหัส | E2: Name | F2: Payment | R2: CS ผู้คีย์บิล
F3: Cash | G3: Credit Card | I3: Tranfer Money | K3: E-WALLET | L3: Paypal | M3: qr paymet | N3: หักคอม | O3: ARP | P3: ยอดในระบบ | Q3: ผลต่าง
G4: Front Office | H4: Online | I4: KBANK | J4: KTB
A5: 1 | B5: 44660 | C5: STHBKK012204001111 | D5: 13762 | E5: นางสาว สุชานันท์ สะตะ | I5: 0 | P5: 32500 | Q5: =SUM(F5+G5+H5+I5+J5+K5+L5+M5+N5+O5-P5) -> -32500 | R5: BKK-Neng
A6: 2 | B6: 44661 | C6: STHBKK012204001112 | D6: 65067 | E6: นาย สัมฤทธิ์ กิ่งภาร + อัญชลี กิ่งภาร | I6: 350 | P6: 350 | Q6: =SUM(F6+G6+H6+I6+J6+K6+L6+M6+N6+O6-P6) -> 0 | R6: Katae BKK
A7: 3 | B7: 44661 | C7: STHBKK012204001113 | D7: 42082 | E7: ณัฐพล เกลี้ยงประไพ | H7: 5000 | P7: 5000 | Q7: =SUM(F7+G7+H7+I7+J7+K7+L7+M7+N7+O7-P7) -> 0 | R7: Katae BKK
A8: 4 | B8: 44661 | C8: STHBKK012204001114 | D8: 42082 | E8: ณัฐพล เกลี้ยงประไพ | H8: 5000 | P8: 5000 | Q8: =SUM(F8+G8+H8+I8+J8+K8+L8+M8+N8+O8-P8) -> 0 | R8: Katae BKK
A9: 5 | B9: 44661 | C9: STHBKK012204001115 | D9: 59285 | E9: นาย ทรงฤทธิ์ เลขไวฑูรย์ | I9: 27000 | P9: 27000 | Q9: =SUM(F9+G9+H9+I9+J9+K9+L9+M9+N9+O9-P9) -> 0 | R9: Katae BKK
A10: 6 | B10: 44661 | C10: STHBKK012204001118 | D10: 55448 | E10: นางสาว วัชรวรรณ นิลสุ | I10: 2650 | P10: 2650 | Q10: =SUM(F10+G10+H10+I10+J10+K10+L10+M10+N10+O10-P10) -> 0 | R10: PoonBKK
A11: 7 | B11: 44661 | C11: STHBKK012204001119 | D11: 47787 | E11: ห้างหุ้นส่วนจำกัด โกรท โกลเบิล เน็ตเวิร์ก (สำนักงานใหญ่) | I11: 2500 | P11: 2500 | Q11: =SUM(F11+G11+H11+I11+J11+K11+L11+M11+N11+O11-P11) -> 0 | R11: PoonBKK
A12: 8 | B12: 44661 | C12: STHBKK012204001120 | D12: 59904 | E12: นาย สุรทัศน์ เกไธสร | I12: 350 | P12: 350 | Q12: =SUM(F12+G12+H12+I12+J12+K12+L12+M12+N12+O12-P12) -> 0 | R12: PoonBKK
A13: 9 | B13: 44661 | C13: STHBKK012204001121 | D13: 67207 | E13: นาง ฐิตารีย์ ธีรรัฐคุณาสิน | J13: 3600 | P13: 3600 | Q13: =SUM(F13+G13+H13+I13+J13+K13+L13+M13+N13+O13-P13) -> 0 | R13: PoonBKK
A14: 10 | B14: 44661 | C14: STHBKK012204001122 | D14: 67207 | E14: นาง ฐิตารีย์ ธีรรัฐคุณาสิน | J14: 4850 | P14: 4850 | Q14: =SUM(F14+G14+H14+I14+J14+K14+L14+M14+N14+O14-P14) -> 0 | R14: PoonBKK
A15: 11 | B15: 44661 | C15: STHBKK012204001124 | D15: 49599 | E15: นาย อภิวัฒน์ หน่ายมี | I15: 1250 | P15: 1250 | Q15: =SUM(F15+G15+H15+I15+J15+K15+L15+M15+N15+O15-P15) -> 0 | R15: PoonBKK
A16: 12 | B16: 44661 | C16: STHBKK012204001126 | D16: 53940 | E16: นาย ปรีชา ศรีคำม้วน | I16: 1400 | P16: 1400 | Q16: =SUM(F16+G16+H16+I16+J16+K16+L16+M16+N16+O16-P16) -> 0 | R16: PoonBKK
A17: 13 | B17: 44661 | C17: STHBKK012204001127 | D17: 50136 | E17: นาย วีระ ชูศิลป์ | I17: 5000 | P17: 5000 | Q17: =SUM(F17+G17+H17+I17+J17+K17+L17+M17+N17+O17-P17) -> 0 | R17: Katae BKK
A18: 14 | B18: 44661 | C18: STHBKK012204001129 | D18: 59377 | E18: นาง วันเพ็ญ โขมพัด | I18: 6600 | P18: 6600 | Q18: =SUM(F18+G18+H18+I18+J18+K18+L18+M18+N18+O18-P18) -> 0 | R18: Katae BKK
A19: 15 | B19: 44661 | C19: STHBKK012204001131 | D19: 44980 | E19: นาย ประทุม สาดทอง | I19: 5350 | P19: 5350 | Q19: =SUM(F19+G19+H19+I19+J19+K19+L19+M19+N19+O19-P19) -> 0 | R19: Katae BKK
A20: 16 | B20: 44661 | C20: STHBKK012204001132 | D20: 69270 | E20: นางสาว ศรีวรรณ์ ศรศิลป์ | J20: 0 | P20: 27000 | Q20: =SUM(F20+G20+H20+I20+J20+K20+L20+M20+N20+O20-P20) -> -27000 | R20: bkk-aoeng
A21: 17 | B21: 44661 | C21: STHBKK012204001133 | D21: 51939 | E21: บริษัท รินทร์รฐา กรุ๊ป จำกัด(สำนักงานใหญ่) | I21: 13200 | P21: 13200 | Q21: =SUM(F21+G21+H21+I21+J21+K21+L21+M21+N21+O21-P21) -> 0 | R21: bkk-aoeng
A22: 18 | B22: 44661 | C22: STHBKK012204001134 | D22: 67120 | E22: นางสาว อารีรัตน์ กู้กำพล | I22: 850 | P22: 850 | Q22: =SUM(F22+G22+H22+I22+J22+K22+L22+M22+N22+O22-P22) -> 0 | R22: Katae BKK
A23: 19 | B23: 44661 | C23: STHBKK012204001135 | D23: 30248 | E23: นางสาว ยุพิน กรลำ | I23: 10000 | P23: 10000 | Q23: =SUM(F23+G23+H23+I23+J23+K23+L23+M23+N23+O23-P23) -> 0 | R23: PoonBKK
A24: 20 | B24: 44661 | C24: STHBKK012204001136 | D24: 39317 | E24: นาง เต็มลักษณ์ ยวงลำใย | J24: 900 | P24: 900 | Q24: =SUM(F24+G24+H24+I24+J24+K24+L24+M24+N24+O24-P24) -> 0 | R24: PoonBKK
A25: 21 | B25: 44661 | C25: STHBKK012204001137 | D25: 68079 | E25: นาย ศุภกฤต เดชะนามเมือง | K25: 150 | P25: 150 | Q25: =SUM(F25+G25+H25+I25+J25+K25+L25+M25+N25+O25-P25) -> 0 | R25: bkk-aoeng
A26: 22 | B26: 44661 | C26: STHBKK012204001138 | D26: 68602 | E26: นาย สุรัตน์ สุขชาวนา | J26: 27000 | P26: 27000 | Q26: =SUM(F26+G26+H26+I26+J26+K26+L26+M26+N26+O26-P26) -> 0 | R26: bkk-aoeng
A27: 23 | B27: 44661 | C27: STHBKK012204001141 | D27: 55895 | E27: นาง บุญมา คลี่แป้ง | I27: 5000 | P27: 5000 | Q27: =SUM(F27+G27+H27+I27+J27+K27+L27+M27+N27+O27-P27) -> 0 | R27: PoonBKK
A28: 24 | B28: 44661 | C28: STHBKK012204001143 | D28: 55895 | E28: นาง บุญมา คลี่แป้ง | I28: 5000 | P28: 5000 | Q28: =SUM(F28+G28+H28+I28+J28+K28+L28+M28+N28+O28-P28) -> 0 | R28: PoonBKK
A29: 25 | B29: 44661 | C29: STHBKK012204001144 | D29: 50692 | E29: นาย สานิต โสมกุล | I29: 10000 | P29: 10000 | Q29: =SUM(F29+G29+H29+I29+J29+K29+L29+M29+N29+O29-P29) -> 0 | R29: PoonBKK
A30: 26 | B30: 44661 | C30: STHBKK012204001145 | D30: 29621 | E30: นางสาว สุดาวรรณ์ จันทร์แดง | J30: 7950 | P30: 7950 | Q30: =SUM(F30+G30+H30+I30+J30+K30+L30+M30+N30+O30-P30) -> 0 | R30: bkk-aoeng
A31: 27 | B31: 44661 | C31: STHBKK012204001147 | D31: 66838 | E31: นาย เสฎฐวุฒิ พนาอภิชน | I31: 16750 | P31: 16750 | Q31: =SUM(F31+G31+H31+I31+J31+K31+L31+M31+N31+O31-P31) -> 0 | R31: PoonBKK
A32: 28 | B32: 44661 | C32: STHBKK012204001148 | D32: 22332 | E32: นางสาว คณาง ไพรบึง | I32: 5775 | P32: 5775 | Q32: =SUM(F32+G32+H32+I32+J32+K32+L32+M32+N32+O32-P32) -> 0 | R32: PoonBKK
